Workbook

Sheet Dbase
A1: KOLOMNR | B1: 2 | C1: 3 | D1: 4 | E1: 5 | F1: 6 | G1: 7 | H1: 8 | I1: 9 | J1: 10 | K1: 11 | L1: 12 | M1: 13 | N1: 14 | O1: 15 | P1: 16 | Q1: 17 | R1: 18 | S1: 19 | T1: 20 | U1: 21 | V1: 22 | W1: 23 | X1: 24 | Y1: 25 | Z1: 26 | AA1: 27 | AB1: 28 | AC1: 29 | AD1: 30 | AE1: 31 | AF1: 32 | AG1: 33 | AH1: 34 | AI1: 35 | AJ1: 36 | AK1: 37 | AL1: 38 | AM1: 39 | AN1: 40 | AO1: 41 | AP1: 42 | AQ1: 43 | AR1: 44 | AS1: 45 | AT1: 46 | AU1: 47 | AV1: 48 | AW1: 49 | AX1: 50 | AY1: 51 | AZ1: 52 | BA1: 53 | BB1: 54 | BC1: 55 | BD1: 56 | BE1: 57 | BF1: 58 | BG1: 59 | BH1: 60 | BI1: 61 | BJ1: 62 | BK1: 63 | BL1: 64 | BM1: 65 | BN1: 66 | BO1: 67 | BP1: 68 | BQ1: 69 | BR1: 70 | BS1: 71 | BT1: 72 | BU1: 73 | BV1: 74 | BW1: 75 | BX1: 76 | BY1: 77 | BZ1: 78 | CA1: 79 | CB1: 80 | CC1: 81 | CD1: 82 | CE1: 83 | CF1: 84 | CG1: 85 | CH1: 86 | CI1: 87 | CJ1: 88 | CK1: 89 | CL1: 90 | CM1: 91 | CN1: 92 | CO1: 93 | CP1: 94 | CQ1: 95 | CR1: 96 | CS1: 97 | CT1: 98 | CU1: 99 | CV1: 100 | CW1: 101 | CX1: 102 | CY1: 103 | CZ1: 104 | DA1: 105 | DB1: 106 | DC1: 107 | DD1: 108 | DE1: 109 | DF1: 110 | DG1: 111 | DH1: 112 | DI1: 113 | DJ1: 114 | DK1: 115 | DL1: 116 | DM1: 117 | DN1: 118 | DO1: 119 | DP1: 120 | DQ1: 121 | DR1: 122 | DS1: 123 | DT1: 124 | DU1: 125 | DV1: 126 | DW1: 127 | DX1: 128 | DY1: 129 | DZ1: 130 | EA1: 131 | EB1: 132 | EC1: 133 | ED1: 134 | EE1: 135 | EF1: 136 | EG1: 137 | EH1: 138 | EI1: 139 | EJ1: 140 | EK1: 141 | EL1: 142 | EM1: 143 | EN1: 144 | EO1: 145 | EP1: 146 | EQ1: 147 | ER1: 148 | ES1: 149 | ET1: 150 | EU1: 151 | EV1: 152 | EW1: 153 | EX1: 154 | EY1: 155 | EZ1: 156 | FA1: 157 | FB1: 158 | FC1: 159 | FD1: 160 | FE1: 161 | FF1: 162 | FG1: 163 | FH1: 164 | FI1: 165 | FJ1: 166 | FK1: 167 | FL1: 168 | FM1: 169 | FN1: 170 | FO1: 171 | FP1: 172 | FQ1: 173 | FR1: 174 | FS1: 175 | FT1: 176 | FU1: 177 | FV1: 178 | FW1: 179 | FX1: 180 | FY1: 181 | FZ1: 182 | GA1: 183 | GB1: 184 | GC1: 185 | GD1: 186 | GE1: 187 | GF1: 188 | GG1: 189 | GH1: 190 | GI1: 191 | GJ1: 192 | GK1: 193 | GL1: 194 | GM1: 195 | GN1: 196 | GO1: 197 | GP1: 198 | GQ1: 199 | GR1: 200 | GS1: 201 | GT1: 202 | GU1: 203 | GV1: 204 | GW1: 205 | GX1: 206 | GY1: 207 | GZ1: 208 | HA1: 209 | HB1: 210 | HC1: 211 | HD1: 212 | HE1: 213 | HF1: 214 | HG1: 215 | HH1: 216 | HI1: 217 | HJ1: 218 | HK1: 219 | HL1: 220 | HM1: 221 | HN1: 222 | HO1: 223 | HP1: 224 | HQ1: 225 | HR1: 226 | HS1: 227 | HT1: 228 | HU1: 229 | HV1: 230 | HW1: 231 | HX1: 232 | HY1: 233 | HZ1: 234 | IA1: 235 | IB1: 236 | IC1: 237 | ID1: 238 | IE1: 239 | IF1: 240 | IG1: 241 | IH1: 242 | II1: 243 | IJ1: 244 | IK1: 245 | IL1: 246 | IM1: 247 | IN1: 248 | IO1: 249 | IP1: 250 | IQ1: 251 | IR1: 252 | IS1: 253 | IT1: 254 | IU1: 255 | IV1: 256 | IW1: 257 | IX1: 258 | IY1: 259 | IZ1: 260 | JA1: 261 | JB1: 262 | JC1: 263 | JD1: 264 | JE1: 265 | JF1: 266 | JG1: 267 | JH1: 268 | JI1: 269 | JJ1: 270 | JK1: 271 | JL1: 272 | JM1: 273 | JN1: 274 | JO1: 275 | JP1: 276 | JQ1: 277 | JR1: 278 | JS1: 279 | JT1: 280 | JU1: 281 | JV1: 282 | JW1: 283 | JX1: 284 | JY1: 285 | JZ1: 286 | KA1: 287 | KB1: 288 | KC1: 289 | KD1: 290 | KE1: 291 | KF1: 292 | KG1: 293 | KH1: 294 | KI1: 295 | KJ1: 296 | KK1: 297 | KL1: 298 | KM1: 299 | KN1: 300 | KO1: 301 | KP1: 302 | KQ1: 303 | KR1: 304 | KS1: 305 | KT1: 306 | KU1: 307 | KV1: 308 | KW1: 309 | KX1: 310 | KY1: 311 | KZ1: 312 | LA1: 313 | LB1: 314 | LC1: 315 | LD1: 316 | LE1: 317 | LF1: 318 | LG1: 319 | LH1: 320 | LI1: 321 | LJ1: 322 | LK1: 323 | LL1: 324 | LM1: 325 | LN1: 326 | LO1: 327 | LP1: 328 | LQ1: 329 | LR1: 330 | LS1: 331 | LT1: 332 | LU1: 333 | LV1: 334 | LW1: 335 | LX1: 336 | LY1: 337 | LZ1: 338 | MA1: 339 | MB1: 340 | MC1: 341 | MD1: 342 | ME1: 343 | MF1: 344 | MG1: 345 | MH1: 346 | MI1: 347 | MJ1: 348 | MK1: 349 | ML1: 350 | MM1: 351 | MN1: 352 | MO1: 353 | MP1: 354 | MQ1: 355 | MR1: 356 | MS1: 357 | MT1: 358 | MU1: 359 | MV1: 360 | MW1: 361 | MX1: 362 | MY1: 363 | MZ1: 364 | NA1: 365 | NB1: 366 | NC1: 367 | ND1: 368 | NE1: 369 | NF1: 370 | NG1: 371 | NH1: 372 | NI1: 373 | NJ1: 374 | NK1: 375 | NL1: 376 | NM1: 377 | NN1: 378 | NO1: 379 | NP1: 380 | NQ1: 381 | NR1: 382 | NS1: 383 | NT1: 384 | NU1: 385 | NV1: 386 | NW1: 387 | NX1: 388 | NY1: 389 | NZ1: 390 | OA1: 391 | OB1: 392 | OC1: 393 | OD1: 394 | OE1: 395 | OF1: 396 | OG1: 397 | OH1: 398 | OI1: 399 | OJ1: 400 | OK1: 401 | OL1: 402 | OM1: 403 | ON1: 404 | OO1: 405 | OP1: 406 | OQ1: 407 | OR1: 408 | OS1: 409 | OT1: 410 | OU1: 411 | OV1: 412 | OW1: 413 | OX1: 414 | OY1: 415 | OZ1: 416 | PA1: 417 | PB1: 418 | PC1: 419 | PD1: 420 | PE1: 421 | PF1: 422 | PG1: 423 | PH1: 424 | PI1: 425 | PJ1: 426 | PK1: 427 | PL1: 428 | PM1: 429 | PN1: 430 | PO1: 431 | PP1: 432 | PQ1: 433 | PR1: 434 | PS1: 435 | PT1: 436 | PU1: 437 | PV1: 438 | PW1: 439 | PX1: 440 | PY1: 441 | PZ1: 442 | QA1: 443 | QB1: 444 | QC1: 445 | QD1: 446 | QE1: 447 | QF1: 448 | QG1: 449 | QH1: 450 | QI1: 451 | QJ1: 452 | QK1: 453 | QL1: 454 | QM1: 455 | QN1: 456 | QO1: 457 | QP1: 458 | QQ1: 459 | QR1: 460 | QS1: 461
A2: NAAM_DBASE | B2: ALG__GRONDSOORT | C2: ALG__VEENCLASSIFICATIE | D2: ALG__KORRELVERDELING | E2: ALG__SONDEERWAARDE | F2: ALG__CRS | G2: ALG__SAMENDRUKKING | H2: ALG__DSS | I2: ALG__TRIAXIAAL | J2: ALG__BORING_MONSTERNR_ID | K2: ALG_OPDRACHTGEVER | L2: ALG_PROJECTNAAM | M2: ALG_PROJECTNUMMER | N2: ALG_NAAM_POLDER_DIJK | O2: ALG_REFERENTIE | P2: ALG_REGIO | Q2: ALG_TYPE_WATERKERING | R2: ALG_AANLEGJAAR | S2: ALG_BODEMKAART | T2: ALG_GEOLOGIE | U2: ALG_FILENAAM_GEOT_PROFIEL | V2: BORING_XID | W2: BORING_YID | X2: BORING_MAAIVELDPEIL | Y2: BORING_NUMMER | Z2: BORING_POSITIE | AA2: BORING_DATUM | AB2: BORING_FILENAAM_PDF | AC2: BORING_FILENAAM_GEF | AD2: BORING_BEDRIJF | AE2: BORING_BOORMEESTER | AF2: BORING_METHODE | AG2: BORING_OPNAME_GWS | AH2: BORING_GLG | AI2: MONSTER_ID | AJ2: MONSTER_STEEKMETHODE | AK2: MONSTER_OPSLAGWIJZE | AL2: MONSTER_NIVEAU_NAP_VANAF | AM2: MONSTER_NIVEAU_NAP_TOT | AN2: MONSTER_NIVEAU_MV_VANAF | AO2: MONSTER_NIVEAU_MV_TOT | AP2: MONSTER_TOTAAL_VOLUMEGEWICHT | AQ2: CLAS_FILENAAM_PDF | AR2: CLAS_FILENAAM_DIGITAAL | AS2: CLAS_MONSTERID | AT2: CLAS_LABORATORIUM | AU2: CLAS_NORMEN | AV2: CLAS_DATUM | AW2: CLAS_GRONDSOORT | AX2: CLAS_OVERIGE_BESTANDDELEN | AY2: CLAS_MONSTERNIVEAU | AZ2: CLAS_VOLUMEGEWICHT_NAT | BA2: CLAS_VOLUMEGEWICHT_DRG | BB2: CLAS_WATERGEHALTE | BC2: CLAS_POROSITEIT | BD2: CLAS_PORIENGETAL | BE2: CLAS_VERZADIGINGSGRAAD | BF2: CLAS_VOLUMEGEWICHT_VERZADIGD | BG2: CLAS_SPECIFIEKE_MASSA_INSCHATTING | BH2: CLAS_SPECIFIEKE_MASSA | BI2: CLAS_GLOEIVERLIES | BJ2: CLAS_KALKGEHALTE | BK2: CLAS_POCKETPENETRO | BL2: CLAS_TORVANE | BM2: CLAS_FALLINGHEAD_K10 | BN2: CLAS_CONSTANTHEAD_K10 | BO2: CLAS_OPMERKING | BP2: CLAS_AT_VLOEIGRENS_CAS | BQ2: CLAS_AT_UITROLGRENS | BR2: CLAS_AT_PI | BS2: CLAS_AT_IC | BT2: CLAS_VN_FILENAAM_PDF | BU2: CLAS_VN_FILENAAM_DIGITAAL | BV2: CLAS_VN_HOOFDNAAM | BW2: CLAS_VN_BOTANISCH | BX2: CLAS_VN_VERWERINGSGRAAD | BY2: CLAS_VN_WATERGEHALTE | BZ2: CLAS_VN_FIJNEVEZELS | CA2: CLAS_VN_GROVEVEZELS | CB2: CLAS_VN_HOUT | CC2: CLAS_VN_GLOEIVERLIES | CD2: CLAS_VN_ASGEHALTE | CE2: KV_FILENAAM_PDF | CF2: KV_FILENAAM_GEF | CG2: KV_MONSTERID | CH2: KV_LABORATORIUM | CI2: KV_NORMEN | CJ2: KV_DATUM | CK2: KV_GRONDSOORT | CL2: KV_OVERIGE_BESTANDDELEN | CM2: KV_MEDIAAN_ZANDFRACTIE | CN2: KV_MEDIAAN_ALLEFRACTIES | CO2: KV_GRIND% | CP2: KV_ZAND% | CQ2: KV_SILT% | CR2: KV_DOOR_63MM | CS2: KV_DOOR_31.5MM | CT2: KV_DOOR_16MM | CU2: KV_DOOR_8MM | CV2: KV_DOOR_4MM | CW2: KV_DOOR_2MM | CX2: KV_DOOR_1MM | CY2: KV_DOOR_500MU | CZ2: KV_DOOR_250MU | DA2: KV_DOOR_180MU | DB2: KV_DOOR_125MU | DC2: KV_DOOR_63MU | DD2: KV_DOOR_32MU | DE2: KV_DOOR_20MU | DF2: KV_DOOR_16MU | DG2: KV_DOOR_2MU | DH2: KV_D70 | DI2: KV_D60 | DJ2: KV_D50 | DK2: KV_D10 | DL2: KV_CU_ZAND | DM2: CPT_FILENAAM_PDF | DN2: CPT_FILENAAM_GEF | DO2: CPT_NIVEAU | DP2: CPT_TRAJECTLENGTE_GEM | DQ2: CPT_CONUSWEERSTAND_GEM | DR2: CPT_WRIJVINGSWEERSTAND_GEM | DS2: CPT_WRIJVINGSGETAL_GEM | DT2: CPT_WATERSPANNING_GEM | DU2: CPT_QNET | DV2: CPT_QT | DW2: CPT_VO | DX2: CPT_KLASSE | DY2: CPT_A_FACTOR | DZ2: CPT_QBALL | EA2: CRS_FILENAAM_PDF | EB2: CRS_FILENAAM_SPANNINGSPAD | EC2: CRS_MONSTERID | ED2: CRS_LABORATORIUM | EE2: CRS_NORM | EF2: CRS_DATUM | EG2: CRS_GRONDSOORT | EH2: CRS_OVERIGE_BESTANDDELEN | EI2: CRS_MONSTERNIVEAU | EJ2: CRS_TERREINSPANNING | EK2: CRS_VOLUMEGEWICHT_NAT | EL2: CRS_VOLUMEGEWICHT_DRG | EM2: CRS_WATERGEHALTE_VOOR | EN2: CRS_WATERGEHALTE_NA_PROEF | EO2: CRS_VERZADIGING | EP2: CRS_TEMPERATUUR_PROEF_MAX | EQ2: CRS_TEMPERATUUR_PROEF_MIN | ER2: CRS_PROEFSTUKDIAMETER_VOOR | ES2: CRS_PROEFSTUKHOOGTE_VOOR | ET2: CRS_PROEFSTUKHOOGTE_NA_VERZADIGING | EU2: CRS_PROEFSTUKHOOGTE_NA_PROEF | EV2: CRS_REKSNELHEID_BELASTEN | EW2: CRS_REKSNELHEID_ONTLASTEN | EX2: CRS_RELAXATIEDUUR | EY2: CRS_EFF_SPANNING_START_RELAXATIE | EZ2: CRS_EFF_SPANNING_EIND_RELAXATIE | FA2: CRS_EFF_VERT_SPANNING_START_ONTLASTEN | FB2: CRS_EFF_VERT_SPANNING_EIND_ONTLASTEN | FC2: CRS_EFF_VERT_SPANNING_EIND_PROEF | FD2: CRS_MAX_REL_WATEROVERSPANNING_PROEF | FE2: CRS_GRENSSPANNING_A | FF2: CRS_REK_BIJ_GRENSSPANNING_A | FG2: CRS_BOVENGRENS_GRENSSPANNING_B | FH2: CRS_ISOTACHE_A | FI2: CRS_ISOTACHE_B | FJ2: CRS_ISOTACHE_C | FK2: SD_FILENAAM_PDF | FL2: SD_FILENAAM_SPANNINGSPAD | FM2: SD_MONSTERID | FN2: SD_LABORATORIUM | FO2: SD_NORM | FP2: SD_DATUM | FQ2: SD_GRONDSOORT | FR2: SD_OVERIGE_BESTANDDELEN | FS2: SD_MONSTERNIVEAU | FT2: SD_TERREINSPANNING | FU2: SD_VOLUMEGEWICHT_NAT | FV2: SD_VOLUMEGEWICHT_DR | FW2: SD_WATERGEHALTE_INI | FX2: SD_WATERGEHALTE_NA_PROEF | FY2: SD_PORIENGETAL | FZ2: SD_MAX_TEMPERATUUR_PROEF | GA2: SD_MIN_TEMPERATUUR_PROEF | GB2: SD_BELAST_ONTLASTSTAPPEN | GC2: SD_TYPEPROEF | GD2: SD_BJERRUM_GRENSSPANNING | GE2: SD_BJERRUM_REK_BIJ_GRENSSPANNING | GF2: SD_BJERRUM_CC | GG2: SD_BJERRUM_CC_TRAP1_2 | GH2: SD_BJERRUM_CC_TRAP2_3 | GI2: SD_BJERRUM_CC_TRAP3_4 | GJ2: SD_BJERRUM_CC_TRAP4_5 | GK2: SD_BJERRUM_CC_TRAP5_6 | GL2: SD_BJERRUM_CC_TRAP6_7 | GM2: SD_BJERRUM_CC_TRAP7_8 | GN2: SD_BJERRUM_CC_TRAP8_9 | GO2: SD_BJERRUM_CC_TRAP9_10 | GP2: SD_BJERRUM_CR | GQ2: SD_BJERRUM_CR_TRAP1_2 | GR2: SD_BJERRUM_CR_TRAP2_3 | GS2: SD_BJERRUM_CR_TRAP3_4 | GT2: SD_BJERRUM_CR_TRAP4_5 | GU2: SD_BJERRUM_CR_TRAP5_6 | GV2: SD_BJERRUM_CR_TRAP6_7 | GW2: SD_BJERRUM_CR_TRAP7_8 | GX2: SD_BJERRUM_SR_TRAP8_9 | GY2: SD_BJERRUM_RR_TRAP9_10 | GZ2: SD_BJERRUM_CALPHA | HA2: SD_BJERRUM_CALPHA_TRAP1 | HB2: SD_BJERRUM_CALPHA_TRAP2 | HC2: SD_BJERRUM_CALPHA_TRAP3 | HD2: SD_BJERRUM_CALPHA_TRAP4 | HE2: SD_BJERRUM_CALPHA_TRAP5 | HF2: SD_BJERRUM_CALPHA_TRAP6 | HG2: SD_BJERRUM_CALPHA_TRAP7 | HH2: SD_BJERRUM_CALPHA_TRAP8 | HI2: SD_BJERRUM_CALPHA_TRAP9 | HJ2: SD_BJERRUM_CALPHA_TRAP10 | HK2: SD_BJERRUM_V0 | HL2: SD_KOPPEJAN_GRENSSPANNING | HM2: SD_KOPPEJAN_REK_BIJ_GRENSSPANNING | HN2: SD_KOPPEJAN_C | HO2: SD_KOPPEJAN_C' | HP2: SD_KOPPEJAN_C_TRAP2_3 | HQ2: SD_KOPPEJAN_C_TRAP3_4 | HR2: SD_KOPPEJAN_C_TRAP4_5 | HS2: SD_KOPPEJAN_C_TRAP5_6 | HT2: SD_KOPPEJAN_C_TRAP6_7 | HU2: SD_KOPPEJAN_C_TRAP7_8 | HV2: SD_KOPPEJAN_C_TRAP8_9 | HW2: SD_KOPPEJAN_CP | HX2: SD_KOPPEJAN_C'P | HY2: SD_KOPPEJAN_CP_TRAP2_3 | HZ2: SD_KOPPEJAN_CP_TRAP3_4 | IA2: SD_KOPPEJAN_CP_TRAP4_5 | IB2: SD_KOPPEJAN_CP_TRAP5_6 | IC2: SD_KOPPEJAN_CP_TRAP6_7 | ID2: SD_KOPPEJAN_CP_TRAP7_8 | IE2: SD_KOPPEJAN_CP_TRAP8_9 | IF2: SD_KOPPEJAN_CS | IG2: SD_KOPPEJAN_C'S | IH2: SD_KOPPEJAN_CS_TRAP2_3 | II2: SD_KOPPEJAN_CS_TRAP3_4 | IJ2: SD_KOPPEJAN_CS_TRAP4_5 | IK2: SD_KOPPEJAN_CS_TRAP5_6 | IL2: SD_KOPPEJAN_CS_TRAP6_7 | IM2: SD_KOPPEJAN_CS_TRAP7_8 | IN2: SD_KOPPEJAN_CS_TRAP8_9 | IO2: SD_ISOTACHE_A | IP2: SD_ISOTACHE_B | IQ2: SD_ISOTACHE_C | IR2: SD_ISOTACHE_GRENSSPANNING_A | IS2: SD_ISOTACHE_REK_BIJ_GRENSSPANNING_A | IT2: SD_ISOTACHE_BOVENGRENS_GRENSSPANNING_B | IU2: SD_CASAGRANDE_CV10_TRAP2 | IV2: SD_CASAGRANDE_CV10_TRAP3 | IW2: SD_CASAGRANDE_CV10_TRAP4 | IX2: SD_CASAGRANDE_CV10_TRAP5 | IY2: SD_CASAGRANDE_CV10_TRAP6 | IZ2: SD_CASAGRANDE_CV10_TRAP7 | JA2: SD_CASAGRANDE_CV10_TRAP8 | JB2: SD_CASAGRANDE_CV10_TRAP9 | JC2: SD_CASAGRANDE_K10_TRAP2 | JD2: SD_CASAGRANDE_K10_TRAP3 | JE2: SD_CASAGRANDE_K10_TRAP4 | JF2: SD_CASAGRANDE_K10_TRAP5 | JG2: SD_CASAGRANDE_K10_TRAP6 | JH2: SD_CASAGRANDE_K10_TRAP7 | JI2: SD_CASAGRANDE_K10_TRAP8 | JJ2: SD_CASAGRANDE_K10_TRAP9 | JK2: SD_CASAGRANDE_MV_TRAP2 | JL2: SD_CASAGRANDE_MV_TRAP3 | JM2: SD_CASAGRANDE_MV_TRAP4 | JN2: SD_CASAGRANDE_MV_TRAP5 | JO2: SD_CASAGRANDE_MV_TRAP6 | JP2: SD_CASAGRANDE_MV_TRAP7 | JQ2: SD_CASAGRANDE_MV_TRAP8 | JR2: SD_CASAGRANDE_MV_TRAP9 | JS2: SD_CASAGRANDE_SPANNING_CV10_TRAP2 | JT2: SD_CASAGRANDE_SPANNING_CV10_TRAP3 | JU2: SD_CASAGRANDE_SPANNING_CV10_TRAP4 | JV2: SD_CASAGRANDE_SPANNING_CV10_TRAP5 | JW2: SD_CASAGRANDE_SPANNING_CV10_TRAP6 | JX2: SD_CASAGRANDE_SPANNING_CV10_TRAP7 | JY2: SD_CASAGRANDE_SPANNING_CV10_TRAP8 | JZ2: SD_CASAGRANDE_SPANNING_CV10_TRAP9 | KA2: SD_TAYLOR_CV10_TRAP2 | KB2: SD_TAYLOR_CV10_TRAP3 | KC2: SD_TAYLOR_CV10_TRAP4 | KD2: SD_TAYLOR_CV10_TRAP5 | KE2: SD_TAYLOR_CV10_TRAP6 | KF2: SD_TAYLOR_CV10_TRAP7 | KG2: SD_TAYLOR_CV10_TRAP8 | KH2: SD_TAYLOR_CV10_TRAP9 | KI2: SD_TAYLOR_K10_TRAP2 | KJ2: SD_TAYLOR_K10_TRAP3 | KK2: SD_TAYLOR_K10_TRAP4 | KL2: SD_TAYLOR_K10_TRAP5 | KM2: SD_TAYLOR_K10_TRAP6 | KN2: SD_TAYLOR_K10_TRAP7 | KO2: SD_TAYLOR_K10_TRAP8 | KP2: SD_TAYLOR_K10_TRAP9 | KQ2: SD_TAYLOR_MV_TRAP2 | KR2: SD_TAYLOR_MV_TRAP3 | KS2: SD_TAYLOR_MV_TRAP4 | KT2: SD_TAYLOR_MV_TRAP5 | KU2: SD_TAYLOR_MV_TRAP6 | KV2: SD_TAYLOR_MV_TRAP7 | KW2: SD_TAYLOR_MV_TRAP8 | KX2: SD_TAYLOR_MV_TRAP9 | KY2: SD_TAYLOR_SPANNING_CV10_TRAP2 | KZ2: SD_TAYLOR_SPANNING_CV10_TRAP3 | LA2: SD_TAYLOR_SPANNING_CV10_TRAP4 | LB2: SD_TAYLOR_SPANNING_CV10_TRAP5 | LC2: SD_TAYLOR_SPANNING_CV10_TRAP6 | LD2: SD_TAYLOR_SPANNING_CV10_TRAP7 | LE2: SD_TAYLOR_SPANNING_CV10_TRAP8 | LF2: SD_TAYLOR_SPANNING_CV10_TRAP9 | LG2: DSS_FILENAAM_PDF | LH2: DSS_FILENAAM_SPANNINGSPAD | LI2: DSS_MONSTERID | LJ2: DSS_LABORATORIUM | LK2: DSS_NORM | LL2: DSS_DATUM | LM2: DSS_GRONDSOORT | LN2: DSS_OVERIGE_BESTANDDELEN | LO2: DSS_MONSTERNIVEAU | LP2: DSS_TERREINSPANNING | LQ2: DSS_VOLUMEGEWICHT_NAT | LR2: DSS_VOLUMEGEWICHT_DRG | LS2: DSS_WATERGEHALTE_VOOR | LT2: DSS_WATERGEHALTE_NA_PROEF | LU2: DSS_VERZADIGINGGRAAD_VOOR | LV2: DSS_PORIENGETAL_VOOR | LW2: DSS_PORIENGETAL_EINDE_CONSOLIDATIE | LX2: DSS_SPECIFIEKE_MASSA | LY2: DSS_TEMPERATUUR_PROEF_MAX | LZ2: DSS_TEMPERATUUR_PROEF_MIN | MA2: DSS_PROEFSTUKDIAMETER_VOOR | MB2: DSS_PROEFSTUKHOOGTE_VOOR | MC2: DSS_PROEFSTUKHOOGTE_NA_CONSOLIDATIE | MD2: DSS_UITGEVOERDE_CORRECTIES | ME2: DSS_UITVOERINGSWIJZE | MF2: DSS_MAX_EFF_VERT_SPANNING_CONSOLIDATIE | MG2: DSS_EFF_VERT_SPANNING_EINDE_CONSOLIDATIE | MH2: DSS_OCR | MI2: DSS_AXIALEREK_EINDE_CONSOLIDATIE | MJ2: DSS_BELASTINGSSTAPPEN_CONSOLIDATIE | MK2: DSS_DUUR_CONSOLIDATIE | ML2: DSS_AFSCHUIFSNELHEID_%UUR | MM2: DSS_AFSCHUIFSNELHEID_MMUUR | MN2: DSS_S_2% | MO2: DSS_T_2% | MP2: DSS_S_5% | MQ2: DSS_T_5% | MR2: DSS_S_10% | MS2: DSS_T_10% | MT2: DSS_S_15% | MU2: DSS_T_15% | MV2: DSS_S_20% | MW2: DSS_T_20% | MX2: DSS_S_BIJ_T_MAX | MY2: DSS_T_MAX | MZ2: DSS_REK_BIJ_T_MAX | NA2: DSS_S_BIJ_T_EIND | NB2: DSS_T_EIND | NC2: DSS_REK_BIJ_T_EIND | ND2: DSS_S_BIJ_MAX_S1S3 | NE2: DSS_T_BIJ_MAX_S1S3 | NF2: DSS_REK_BIJ_MAX_S1S3 | NG2: DSS_SCHUIFMODULUS_G50 | NH2: TXT_SS_FILENAAM_PDF | NI2: TXT_SS_FILENAAM_SPANNINGSPAD | NJ2: TXT_SS_MONSTERID | NK2: TXT_SS_LABORATORIUM | NL2: TXT_SS_NORM | NM2: TXT_SS_DATUM | NN2: TXT_SS_GRONDSOORT | NO2: TXT_SS_OVERIGE_BESTANDDELEN | NP2: TXT_SS_MONSTERNIVEAU | NQ2: TXT_SS_TERREINSPANNING | NR2: TXT_SS_VOLUMEGEWICHT_NAT | NS2: TXT_SS_VOLUMEGEWICHT_DRG | NT2: TXT_SS_WATERGEHALTE_NA_PROEF | NU2: TXT_SS_WATERGEHALTE_VOOR | NV2: TXT_SS_VERZADIGINGSGRAAD_VOOR | NW2: TXT_SS_PORIENGETAL_VOOR | NX2: TXT_SS_SPECIFIEKE_MASSA | NY2: TXT_SS_TEMPERATUUR_PROEF_MAX | NZ2: TXT_SS_TEMPERATUUR_PROEF_MIN | OA2: TXT_SS_PROEFSTUKDIAMETER_VOOR | OB2: TXT_SS_PROEFSTUKHOOGTE_VOOR | OC2: TXT_SS_TYPE_PROEF | OD2: TXT_SS_MEMBRAANCORRECTIE | OE2: TXT_SS_OVERIGECORRECTIES | OF2: TXT_SS_BACKPRESSURE | OG2: TXT_SS_CONSOLIDATIEWIJZE | OH2: TXT_SS_SPANNINGSVERHOUDING_STOPCR_K | OI2: TXT_SS_STOPCRITERIUM_CONSOLIDATIE | OJ2: TXT_SS_S'_ISOTROOP_CONSOLIDATIE | OK2: TXT_SS_T_ISOTROOP_CONSOLIDATIE | OL2: TXT_SS_S'_MAX_CONSOLIDATIE | OM2: TXT_SS_T_MAX_CONSOLIDATIE | ON2: TXT_SS_S'_EIND_CONSOLIDATIE | OO2: TXT_SS_T_EIND_CONSOLIDATIE | OP2: TXT_SS_OCR | OQ2: TXT_SS_AXIALEREK_CONSOLIDATIE | OR2: TXT_SS_VOLUMEREK_CONSOLIDATIE | OS2: TXT_SS_STOPCRITERIUM_AFSCHUIVEN | OT2: TXT_SS_AXIALEREKSNELHEID_AFSCHUIVEN | OU2: TXT_SS_S'_2% | OV2: TXT_SS_T_2% | OW2: TXT_SS_S'_5% | OX2: TXT_SS_T_5% | OY2: TXT_SS_S'_15% | OZ2: TXT_SS_T_15% | PA2: TXT_SS_S'_BIJ_T_PIEK | PB2: TXT_SS_T_PIEK | PC2: TXT_SS_REK_BIJ_T_PIEK | PD2: TXT_SS_S'_BIJ_T_EIND | PE2: TXT_SS_T_EIND | PF2: TXT_SS_REK_BIJ_T_EIND | PG2: TXT_SS_E_UNDR50 | PH2: TXT_SS_REK_BIJ_E_UNDR50 | PI2: TXT_SS_SKEMPTON_A | PJ2: TXT_MS_FILENAAM_PDF | PK2: TXT_MS_FILENAAM_SPANNINGSPAD | PL2: TXT_MS_MONSTERID | PM2: TXT_MS_LABORATORIUM | PN2: TXT_MS_CONSOLIDATIESPANNING | PO2: TXT_MS_REK_BIJ_E_UNDR50 | PP2: TXT_MS_E_UNDR50 | PQ2: TXT_MS_S1'_2% | PR2: TXT_MS_S2'_2% | PS2: TXT_MS_S3'_2% | PT2: TXT_MS_T1_2% | PU2: TXT_MS_T2_2% | PV2: TXT_MS_T3_2% | PW2: TXT_MS_C_2% | PX2: TXT_MS_PHI_2% | PY2: TXT_MS_S1'_5% | PZ2: TXT_MS_S2'_5% | QA2: TXT_MS_S3'_5% | QB2: TXT_MS_T1_5% | QC2: TXT_MS_T2_5% | QD2: TXT_MS_T3_5% | QE2: TXT_MS_C_5% | QF2: TXT_MS_PHI_5% | QG2: CEL_FILENAAM_PDF | QH2: CEL_FILENAAM_SPANNINGSPAD | QI2: CEL_PHI1 | QJ2: CEL_C1 | QK2: CEL_PHI2 | QL2: CEL_C2 | QM2: CEL_PHI3 | QN2: CEL_C3 | QO2: CEL_PHI4 | QP2: CEL_C4 | QQ2: CEL_PHI5 | QR2: CEL_C5 | QS2: CEL_EINDSPANNING
A3: EENHEID | B3: - | C3: - | D3: - | E3: - | F3: - | G3: - | H3: - | I3: - | J3: - | K3: - | L3: - | M3: - | N3: - | O3: - | P3: - | Q3: - | R3: - | S3: - | T3: - | U3: - | V3: m | W3: m | X3: m NAP | Y3: - | Z3: - | AA3: DD-MM-JJJJ | AB3: - | AC3: - | AD3: - | AE3: - | AF3: - | AG3: m NAP | AH3: m NAP | AI3: - | AJ3: - | AK3: - | AL3: m NAP | AM3: m NAP | AN3: m | AO3: m | AP3: kN/m3 | AQ3: - | AR3: - | AS3: - | AT3: - | AU3: - | AV3: DD-MM-JJJJ | AW3: - | AX3: - | AY3: m NAP | AZ3: kN/m3 | BA3: kN/m3 | BB3: % | BC3: % | BD3: - | BE3: % | BF3: kN/m3 | BG3: kg/m3 | BH3: kg/m3 | BI3: % | BJ3: % | BK3: kPa | BL3: kPa | BM3: m/s | BN3: m/s | BO3: - | BP3: % | BQ3: % | BR3: % | BS3: - | BT3: - | BU3: - | BV3: - | BW3: - | BX3: - | BY3: - | BZ3: - | CA3: - | CB3: - | CC3: % | CD3: % | CE3: - | CF3: - | CG3: - | CH3: - | CI3: - | CJ3: DD-MM-JJJJ | CK3: - | CL3: - | CM3: mu | CN3: mu | CO3: % | CP3: % | CQ3: % | CR3: % | CS3: % | CT3: % | CU3: % | CV3: % | CW3: % | CX3: % | CY3: % | CZ3: % | DA3: % | DB3: % | DC3: % | DD3: % | DE3: % | DF3: % | DG3: % | DH3: mu | DI3: mu | DJ3: mu | DK3: mu | DL3: - | DM3: - | DN3: - | DO3: m NAP | DP3: cm | DQ3: kPa | DR3: kPa | DS3: - | DT3: kPa | DU3: kPa | DV3: kPa | DW3: kPa | DX3: - | DY3: - | DZ3: kPa | EA3: - | EB3: - | EC3: - | ED3: - | EE3: - | EF3: DD-MM-JJJJ | EG3: - | EH3: - | EI3: m NAP | EJ3: kPa | EK3: kN/m3 | EL3: kN/m3 | EM3: % | EN3: % | EO3: kPa | EP3: °C | EQ3: °C | ER3: mm | ES3: mm | ET3: mm | EU3: mm | EV3: %/uur | EW3: %/uur | EX3: uur | EY3: kPa | EZ3: kPa | FA3: kPa | FB3: kPa | FC3: kPa | FD3: - | FE3: kPa | FF3: % | FG3: kPa | FH3: - | FI3: - | FJ3: - | FK3: - | FL3: - | FM3: - | FN3: - | FO3: - | FP3: DD-MM-JJJJ | FQ3: - | FR3: - | FS3: m NAP | FT3: kPa | FU3: kN/m3 | FV3: kN/m3 | FW3: % | FX3: % | FY3: - | FZ3: °C | GA3: °C | GB3: - | GC3: - | GD3: kPa | GE3: % | GF3: - | GG3: - | GH3: - | GI3: - | GJ3: - | GK3: - | GL3: - | GM3: - | GN3: - | GO3: - | GP3: - | GQ3: - | GR3: - | GS3: - | GT3: - | GU3: - | GV3: - | GW3: - | GX3: - | GY3: - | GZ3: - | HA3: - | HB3: - | HC3: - | HD3: - | HE3: - | HF3: - | HG3: - | HH3: - | HI3: - | HJ3: - | HK3: - | HL3: kPa | HM3: % | HN3: - | HO3: - | HP3: - | HQ3: - | HR3: - | HS3: - | HT3: - | HU3: - | HV3: - | HW3: - | HX3: - | HY3: - | HZ3: - | IA3: - | IB3: - | IC3: - | ID3: - | IE3: - | IF3: - | IG3: - | IH3: - | II3: - | IJ3: - | IK3: - | IL3: - | IM3: - | IN3: - | IO3: - | IP3: - | IQ3: - | IR3: kPa | IS3: % | IT3: kPa | IU3: m2/s | IV3: m2/s | IW3: m2/s | IX3: m2/s | IY3: m2/s | IZ3: m2/s | JA3: m2/s | JB3: m2/s | JC3: m/s | JD3: m/s | JE3: m/s | JF3: m/s | JG3: m/s | JH3: m/s | JI3: m/s | JJ3: m/s | JK3: 1/MPa | JL3: 1/MPa | JM3: 1/MPa | JN3: 1/MPa | JO3: 1/MPa | JP3: 1/MPa | JQ3: 1/MPa | JR3: 1/MPa | JS3: kPa | JT3: kPa | JU3: kPa | JV3: kPa | JW3: kPa | JX3: kPa | JY3: kPa | JZ3: kPa | KA3: m2/s | KB3: m2/s | KC3: m2/s | KD3: m2/s | KE3: m2/s | KF3: m2/s | KG3: m2/s | KH3: m2/s | KI3: m/s | KJ3: m/s | KK3: m/s | KL3: m/s | KM3: m/s | KN3: m/s | KO3: m/s | KP3: m/s | KQ3: 1/MPa | KR3: 1/MPa | KS3: 1/MPa | KT3: 1/MPa | KU3: 1/MPa | KV3: 1/MPa | KW3: 1/MPa | KX3: 1/MPa | KY3: kPa | KZ3: kPa | LA3: kPa | LB3: kPa | LC3: kPa | LD3: kPa | LE3: kPa | LF3: kPa | LG3: - | LH3: - | LI3: - | LJ3: - | LK3: - | LL3: DD-MM-JJJJ | LM3: - | LN3: - | LO3: m NAP | LP3: kPa | LQ3: kN/m3 | LR3: kN/m3 | LS3: % | LT3: % | LU3: % | LV3: - | LW3: - | LX3: kg/m3 | LY3: °C | LZ3: °C | MA3: mm | MB3: mm | MC3: mm | MD3: - | ME3: - | MF3: kPa | MG3: kPa | MH3: - | MI3: % | MJ3: - | MK3: uur | ML3: %/uur | MM3: mm/uur | MN3: kPa | MO3: kPa | MP3: kPa | MQ3: kPa | MR3: kPa | MS3: kPa | MT3: kPa | MU3: kPa | MV3: kPa | MW3: kPa | MX3: kPa | MY3: kPa | MZ3: % | NA3: kPa | NB3: kPa | NC3: % | ND3: NVT | NE3: NVT | NF3: NVT | NG3: kPa | NH3: - | NI3: - | NJ3: - | NK3: - | NL3: - | NM3: DD-MM-JJJJ | NN3: - | NO3: - | NP3: m NAP | NQ3: kPa | NR3: kN/m3 | NS3: kN/m3 | NT3: % | NU3: % | NV3: % | NW3: - | NX3: kg/m3 | NY3: °C | NZ3: °C | OA3: mm | OB3: mm | OC3: - | OD3: - | OE3: - | OF3: kPa | OG3: - | OH3: - | OI3: - | OJ3: kPa | OK3: kPa | OL3: kPa | OM3: kPa | ON3: kPa | OO3: kPa | OP3: - | OQ3: % | OR3: % | OS3: % | OT3: %/uur | OU3: kPa | OV3: kPa | OW3: kPa | OX3: kPa | OY3: kPa | OZ3: kPa | PA3: kPa | PB3: kPa | PC3: % | PD3: kPa | PE3: kPa | PF3: % | PG3: MPa | PH3: % | PI3: - | PJ3: - | PK3: - | PL3: - | PM3: - | PN3: kPa | PO3: % | PP3: MPa | PQ3: kPa | PR3: kPa | PS3: kPa | PT3: kPa | PU3: kPa | PV3: kPa | PW3: kPa | PX3: ° | PY3: kPa | PZ3: kPa | QA3: kPa | QB3: kPa | QC3: kPa | QD3: kPa | QE3: kPa | QF3: ° | QG3: - | QH3: - | QI3: ° | QJ3: kPa | QK3: ° | QL3: kPa | QM3: ° | QN3: kPa | QO3: ° | QP3: kPa | QQ3: ° | QR3: kPa | QS3: kPa
A4: OMSCHRIJVING_PARAMETER | B4: Geeft aan of classificatieproeven zijn uitgevoerd [WAAR/ONWAAR of TRUE/FALSE] | C4: Geeft aan of classificatieproeven op veen zijn uitgevoerd [WAAR/ONWAAR of TRUE/FALSE] | D4: Geeft aan of een korrelverdeling is uitgevoerd [WAAR/ONWAAR of TRUE/FALSE] | E4: Geeft aan of (gemiddelde) sondeerwaarde beschikbaar zijn op de diepte van de uitgevoerde proeven [WAAR/ONWAAR of TRUE/FALSE] | F4: Geeft aan of een CRS-proef is uitgevoerd [WAAR/ONWAAR of TRUE/FALSE] | G4: Geeft aan of een samendrukkingsproef is uitgevoerd [WAAR/ONWAAR of TRUE/FALSE] | H4: Geeft aan of een direct simple shearproef is uitgevoerd [WAAR/ONWAAR of TRUE/FALSE] | I4: Geeft aan of een triaxiaalproef is uitgevoerd [WAAR/ONWAAR of TRUE/FALSE] | J4: Combinatie tussen regelnummer, boring en monsternummer | K4: Naam van de opdrachtgever | L4: Projectnaam | M4: Projectnummer van de uitvoerende organisatie | N4: Naam van de polder of dijk | O4: Refentie voor de vastlegging van de posititie van het onderzoek binnen het dijkvak, bijv. ten opzichte van dijkpaal | P4: Naam van de gemeente | Q4: Beschrijving van de type kade of dijk | R4: Jaar aanleg | S4: Bodemkaart NL soortnaam | T4: Naam van de geologische afzetting waartoe de onderzochte laag toe behoort | U4: Bestandsnaam van het bestand waarin het geotechnisch lengteprofiel is opgenomen | V4: X-coordinaat van boring waaruit de monsters van de proeven afkomstig zijn. Coordinaten weergeven in RD-coordinaten | W4: Y-coordinaat van boring waaruit de monsters van de proeven afkomstig zijn. Coordinaten weergeven in RD-coordinaten | X4: De maaiveldhoogte ter plaatse van de boring. | Y4: Nummering van de boring | Z4: Locatie van de boring ten opzicht van de waterkeringen. Mogelijkheden zijn: kruin, binnentalud, buitentalud, teen, achterland / KR, BITA, BUTA, BUT, BIT, AL | AA4: Datum waarop de boring is uitgevoerd | AB4: Bestandnaam van de pdf waarin de boring is gerapporteerd | AC4: Bestandsnaam van het GEF-bestand waarin de beschrijving van de boring is opgenomen | AD4: Naam van het bedrijf dat de boring heeft uitgevoerd | AE4: Naam van de boormeester die de boring heeft uitgevoerd | AF4: Methode van boren en monstername | AG4: De tijdens het boren gemeten grondwaterstand in het boorgat | AH4: De tijdens het boren vastgestelde GLG (Gemiddeld Laagste Grondwaterstand) | AI4: Monsternummering van de boring | AJ4: Methode van steken / drukken van ongeroerde / geroerde monster. Bijvoorbeeld: Ackerman, dunwandig, ongeroerd, gedrukt | AK4: Beschrijving van de manier hoe de monsters in het laboratorium zijn opgeslagen voorafgaand aan de proeven. | AL4: Niveau van het monster (bovenkant) van de classificatieproeven tov m NAP | AM4: Niveau van het monster (onderkant) van de classificatieproeven tov m NAP | AN4: Niveau van het monster (bovenkant) van de classificatieproeven tov m MV | AO4: Niveau van het monster (onderkant) van de classificatieproeven tov m MV | AP4: Meting van het totale volumegewicht van het monstermateriaal (gecorrigeerd o.b.v. volume monster) | AQ4: Bestandnaam van de pdf waarin de classificatieproeven zijn gerapporteerd | AR4: Bestandsnaam van de file waarin de gegevens van de classificatie conform het STOWA-format is opgenomen | AS4: Monsternummering van de classificatieproeven | AT4: Laboratorium waar de classificatie en veenclassificatie uitgevoerd zijn. | AU4: Bij de classificatie aangehouden normen | AV4: Datum waarop de classificatieproeven zijn uitgevoerd | AW4: Classificatie van de grond conform de gehanteerde norm | AX4: Beschrijving van de bijzondere bestanddelen of secundaire of tertiaire fracties | AY4: Niveau van het monster van de classificatie-proef | AZ4: Resultaat van de bepaling van het initiele volumieke gewicht conform NEN5110/5111 | BA4: Resultaat van de bepaling van het droge volumieke gewicht conform NEN5110/5111 | BB4: Resultaat van de bepaling van het initiele watergehalte conform NEN5112/5113 | BC4: Resultaat van de bepaling van de porositeit | BD4: Resultaat van de bepaling van het poriengetal conform ... | BE4: Verzadigingsgraad van het monster (0-100%) | BF4: Inschatting van het verzadigde volumegewicht | BG4: Inschatting van de dichtheid of specifieke massa volgens standaardgetal (2650 kg/m3), relaties of ervaringsdatabases | BH4: Resultaat van de bepaling van de dichtheid of specifieke massa conform ... | BI4: Resultaat van de bepaling van het verlies aan organisch materiaal bij verhitting tot 500°C/550°C. Het gloeiverlies wordt hiermee bepaald. Het gloeiverlies is niet gelijk aan het asgehalte. Het asgehalte kan bepaald worden aan de hand van het gloeiverlies: asgehalte = 1.04 x (100 - gloeiverlies [%]) | BJ4: Resultaat van de bepaling van het verlies aan kalk bij verhitting tot 900°C | BK4: Resultaat van de bepaling van de sterkte met de pocket penetrometer conform ... | BL4: Resultaat van de bepaling van de sterkte met de torvaneproef conform NEN5106 | BM4: Falling headk10 | BN4: Constant head k10 | BO4: Opmerkingen | BP4: Resultaat van de bepaling van de vloeigrens conform ... | BQ4: Resultaat van de bepaling van de uitrolgrens conform ... | BR4: Plasticiteitsindex | BS4: Consistentieindex | BT4: Bestandsnaam van de pdf-file waarin de gegevens van de veenclassificatie zijn opgenomen | BU4: Bestandsnaam van de file waarin de gegevens van de veenclassificatie conform het STOWA-format is opgenomen | BV4: Classificatie van het veen conform de TAW-leidraad TR16 Geotechnische classificatie van veen. Hoofdnaam van het veen. [V, Vk1, Vk2, Vz1, Vz3] | BW4: Classificatie van het veen conform de TAW-leidraad TR16 Geotechnische classificatie van veen. Botanische samenstelling. [Sch, Ph, C, W, N Er, S, H, B] | BX4: Classificatie van het veen conform de TAW-leidraad TR16 Geotechnische classificatie van veen. Verweringsgraad volgens Von Post [H'1, H'2 , H'3, H;4] | BY4: Classificatie van het veen conform de TAW-leidraad TR16 Geotechnische classificatie van veen. Watergehalte [B1, B2, B3, B4, B5] | BZ4: Classificatie van het veen conform de TAW-leidraad TR16 Geotechnische classificatie van veen. Gehalte aan fijne vezels [F0, F1, F2, F3] | CA4: Classificatie van het veen conform de TAW-leidraad TR16 Geotechnische classificatie van veen. Gehalte aan grove vezels [R0, R1, R2, R3] | CB4: Classificatie van het veen conform de TAW-leidraad TR16 Geotechnische classificatie van veen. Gehalte aan hout [W0, W1, W2, W3] | CC4: Classificatie van het veen conform de TAW-leidraad TR16 Geotechnische classificatie van veen. Resultaat van de bepaling van het gloeiverlies in %. Gloeiverlies is (de massa voor verassing minus de massa na verassing) in verhouding tot (de massa na verassing). Op basis van het gloeiverlies kan het asgehalte bepaald worden. | CD4: Classificatie van het veen conform de TAW-leidraad TR16 Geotechnische classificatie van veen. Gehalte aan as [N1, N2, N3, N4]. Het asgehalte is te bepalen op basis van het gloeiverlies. Het asgehalte is 1,04 maal (100% minus het gloeiverlies in %). | CE4: Bestandnaam van de pdf waarin de korrelverdeling is gerapporteerd | CF4: Bestandsnaam van het GEF-bestand waarin de gegevens van de korrelverdeling is opgenomen | CG4: Monsternummering van de zeefproeven | CH4: Laboratorium waar de zeefproeven zijn uitgevoerd | CI4: Bij de zeefproeven aangehouden normen | CJ4: Datum waarop de zeefproeven zijn uitgevoerd | CK4: Classificatie van de grond conform de gehanteerde norm | CL4: Beschrijving van de bijzondere bestanddelen of secundaire of tertiaire fracties | CM4: De zandmediaan is de korreldiameter waarbij 50% van de zandfractie kleiner is dan deze korreldiameter. (is gelijk aan D50) | CN4: De mediaan wordt bepaald over het gehele monster en niet over alleen de zandfractie. De mediaan is de korreldiameter waarbij 50% van de gehele fractie kleiner is dan deze diameter. | CO4: Percentage grind % grind>2mm | CP4: Percentage zand % zand tussen 0,063 - 2 mm | CQ4: Percentage silt % silt tussen 0,002 - 0,063 mm | CR4: Gewichtspercentage van het gehele monster dat kleiner is dan 63 mm | CS4: Gewichtspercentage van het gehele monster dat kleiner is dan 31,5 mm | CT4: Gewichtspercentage van het gehele monster dat kleiner is dan 16 mm | CU4: Gewichtspercentage van het gehele monster dat kleiner is dan 8 mm | CV4: Gewichtspercentage van het gehele monster dat kleiner is dan 4 mm | CW4: Gewichtspercentage van het gehele monster dat kleiner is dan 2 mm | CX4: Gewichtspercentage van het gehele monster dat kleiner is dan 1 mm | CY4: Gewichtspercentage van het gehele monster dat kleiner is dan 500 mu | CZ4: Gewichtspercentage van het gehele monster dat kleiner is dan 250 mu | DA4: Gewichtspercentage van het gehele monster dat kleiner is dan 180 mu | DB4: Gewichtspercentage van het gehele monster dat kleiner is dan 125 mu | DC4: Gewichtspercentage van het gehele monster dat kleiner is dan 63 mu | DD4: Gewichtspercentage van het gehele monster dat kleiner is dan 32 mu | DE4: Gewichtspercentage van het gehele monster dat kleiner is dan 20 mu | DF4: Gewichtspercentage van het gehele monster dat kleiner is dan 16 mu | DG4: Gewichtspercentage van het gehele monster dat kleiner is dan 2 mu | DH4: De korreldiameter waarbij 70% van de zandfractie kleiner is dan deze korreldiameter | DI4: De korreldiameter waarbij 60% van de zandfractie kleiner is dan deze korreldiameter | DJ4: De korreldiameter waarbij 50% van de zandfractie kleiner is dan deze korreldiameter (D50 is gelijk aan de Zandmediaan) | DK4: De korreldiameter waarbij 10% van de zandfractie kleiner is dan deze korreldiameter | DL4: De gelijkmatigheidscoefficient Cu van de zandfractie. Bepaald door D60/D10 van het materiaal tussen 63 mu en 2 mm. | DM4: Bestandsnaam van het GEF-bestand dat gebruikt is bij de bepaling van de gemiddelde waarden uit de sondering op de diepte van het monsterniveau (#CPT_NIVEAU). | DN4: Bestandsnaam van het GEF-bestand dat gebruikt is bij de bepaling van de gemiddelde waarden uit de sondering op de diepte van het monsterniveau (#CPT_NIVEAU). | DO4: Monsterniveaus waarbij de bepaling van de gemiddelde waarden uit de sondering is bepaald. Het traject waarover gemiddeld is loopt van 0.5 x trajectlengte (#CPT_TRAJECTLENGTE) boven het monsterniveau (#CPT_NIVEAU) tot 0.5 x trjactlengte beneden het monsterniveau. | DP4: Lengte waarover de gemiddelde sondeerwaarden zijn bepaald. | DQ4: Gemiddelde conusweerstand gemeten tijdens de sondering op het monsterniveau (#CPT_NIVEAU) over een bepaalde lengte (#CPT_TRAJECTLENGTE) | DR4: Gemiddelde wrijvingsweerstand gemeten tijdens de sondering op het monsterniveau (#CPT_NIVEAU) over een bepaalde lengte (#CPT_TRAJECTLENGTE) | DS4: Gemiddelde wrijvingsgetal op het monsterniveau (#CPT_NIVEAU) over een bepaalde lengte (#CPT_TRAJECTLENGTE) bepaald uit de gemeten conusweerstand (#CPT_CONUSWEERSTAND_GEM) en de gemeten wrijvingsweerstand (#CPT_WRIJVINGSWEERSTAND_GEM) | DT4: Gemiddelde waterspanning gemeten tijdens de sondering op het monsterniveau (#CPT_NIVEAU) over een bepaalde lengte (#CPT_TRAJECTLENGTE) | DU4: Netto conusweerstand = qnet = qt - σv0 | DV4: Conusweerstand gecorrigeerd voor gemeten waterspanning qt = qc + (1-a).u2 | DW4: Verticale grondspanning σv0 (totaalspanning) | DX4: Sonderingklasse 1 of 2 | DY4: netto oppervlakteverhoudingscoëfficiënt van de conus = a | DZ4: qball weerstandbolsonde | EA4: Bestandnaam van de pdf waarin de CRS-proef is gerapporteerd | EB4: Bestandsnaam van de file waarin het spanningspad conform het STOWA-format is opgenomen | EC4: Monsternummering van de CRS-proef | ED4: Laboratorium waar de CRS-proef is uitgevoerd | EE4: Bij de uitvoering van de CRS-proef aangehouden normen | EF4: Datum waarop de CRS-proef is uitgevoerd | EG4: Classificatie van de grond conform de gehanteerde norm | EH4: Beschrijving van de bijzondere bestanddelen of secundaire of tertiaire fracties | EI4: Niveau van het monster van de CRS-proef | EJ4: Inschatting van de terreinspanning op het niveau van het beproefde monster | EK4: Resultaat van de bepaling van het initiele volumieke gewicht conform NEN5110/5111 voor uitvoering van de proef | EL4: Resultaat van de bepaling van het droge volumieke gewicht conform NEN5110/5111 voor uitvoering van de proef | EM4: Resultaat van de bepaling van het initiele watergehalte conform NEN5112/5113 voor uitvoering van de proef | EN4: Resultaat van de bepaling van het initiele watergehalte conform NEN5112/5113 na uitvoering van de proef | EO4: Verzadigingsniveau van het monster | EP4: Maximum temperatuur in het laboratorium gedurende de uitvoering van de proef | EQ4: Minimum temperatuur in het laboratorium gedurende de uitvoering van de proef | ER4: Diameter van het proefstuk dat in het CRS-apparaat is beproefd voor beproeving | ES4: Hoogte van het proefstuk dat in het CRS-apparaat is beproefd voor beproeving | ET4: Hoogte van het proefstuk dat in het CRS-apparaat is beproefd na verzadiging | EU4: Hoogte van het proefstuk dat in het CRS-apparaat is beproefd na beproeving | EV4: Reksnelheid waarm het monster tijdens het belasten is belast | EW4: Reksnelheid waarm het monster tijdens het ontlasten is ontlast | EX4: De duur van de relaxatiefase | EY4: Effectieve spanning bij de start van de relaxatiefase | EZ4: Effectieve spanning aan het eind van de relaxatiefase | FA4: Effectieve verticale spanning bij de start van het ontlasten | FB4: Effectieve verticale spanning aan het eind van het ontlasten | FC4: Effectieve verticale spanning aan het eind van de proef | FD4: Maximale relatieve wateroverspanning tijdens de proef | FE4: Grensspanning A | FF4: De rek waarbij de grensspanning A is bepaald | FG4: De bovengrens voor de grensspanning B | FH4: Waarde van de a-parameters van de isotachen | FI4: Waarde van de b-parameters van de isotachen | FJ4: Waarde van de c-parameters van de isotachen | FK4: Bestandnaam van de pdf waarin de samendrukkings-proef is gerapporteerd | FL4: Bestandsnaam van de file waarin het spanningspad conform het STOWA-format is opgenomen | FM4: Monsternummering van de samendrukkingsproef | FN4: Laboratorium waar de samendrukkingsproef is uitgevoerd | FO4: Bij de uitvoering van de samendrukkingsproef aangehouden normen | FP4: Datum waarop de samendrukkingsproef is uitgevoerd | FQ4: Classificatie van de grond conform de gehanteerde norm | FR4: Beschrijving van de bijzondere bestanddelen of secundaire of tertiaire fracties | FS4: Niveau van het monster van de samendrukkingsproef | FT4: Inschatting van de terreinspanning op het niveau van het beproefde monster | FU4: Resultaat van de bepaling van het initiele volumieke gewicht conform NEN5110/5111 voor uitvoering van de proef | FV4: Resultaat van de bepaling van het droge volumieke gewicht conform NEN5110/5111 voor uitvoering van de proef | FW4: Resultaat van de bepaling van het initiele watergehalte conform NEN5112/5113 voor uitvoering van de proef | FX4: Resultaat van de bepaling van het initiele watergehalte conform NEN5112/5113 na uitvoering van de proef | FY4: Resultaat van de bepaling van het poriengetal conform ... | FZ4: Maximum temperatuur in het laboratorium gedurende de uitvoering van de proef | GA4: Minimum temperatuur in het laboratorium gedurende de uitvoering van de proef | GB4: Aantal belasttrappen en het aantal ontlasttrappen | GC4: Beschrijving van de type uitgevoerde proef | GD4: Samendrukkingsparameter volgens Bjerrum, grensspanning | GE4: Samendrukkingsparameter volgens Bjerrum, rek bij de grensspanning | GF4: NEN Bjerrum Cc | GG4: Samendrukkingsparameter volgens Bjerrum, Cc waarde conform NEN5118, trap 1-2 | GH4: Samendrukkingsparameter volgens Bjerrum, Cc waarde conform NEN5118, trap 2-3 | GI4: Samendrukkingsparameter volgens Bjerrum, Cc waarde conform NEN5118, trap 3-4 | GJ4: Samendrukkingsparameter volgens Bjerrum, Cc waarde conform NEN5118, trap 4-5 | GK4: Samendrukkingsparameter volgens Bjerrum, Cc waarde conform NEN5118, trap 5-6 | GL4: Samendrukkingsparameter volgens Bjerrum, Cc waarde conform NEN5118, trap 6-7 | GM4: Samendrukkingsparameter volgens Bjerrum, Cc waarde conform NEN5118, trap 7-8 | GN4: Samendrukkingsparameter volgens Bjerrum, Cc waarde conform NEN5118, trap 8-9 | GO4: Samendrukkingsparameter volgens Bjerrum, Cc waarde conform NEN5118, trap 9-10 | GP4: NEN Bjerrum Cr | GQ4: Samendrukkingsparameter volgens Bjerrum, CR waarde conform NEN5118, trap 1-2 | GR4: Samendrukkingsparameter volgens Bjerrum, CR waarde conform NEN5118, trap 2-3 | GS4: Samendrukkingsparameter volgens Bjerrum, CR waarde conform NEN5118, trap 3-4 | GT4: Samendrukkingsparameter volgens Bjerrum, CR waarde conform NEN5118, trap 4-5 | GU4: Samendrukkingsparameter volgens Bjerrum, CR waarde conform NEN5118, trap 5-6 | GV4: Samendrukkingsparameter volgens Bjerrum, CR waarde conform NEN5118, trap 6-7 | GW4: Samendrukkingsparameter volgens Bjerrum, CR waarde conform NEN5118, trap 7-8 | GX4: Samendrukkingsparameter volgens Bjerrum, CR waarde conform NEN5118, trap 8-9 | GY4: Samendrukkingsparameter volgens Bjerrum, CR waarde conform NEN5118, trap 9-10 | GZ4: NEN Bjerrum Calpha | HA4: Samendrukkingsparameter volgens Bjerrum, Calpha trap 1 | HB4: Samendrukkingsparameter volgens Bjerrum, Calpha trap 2 | HC4: Samendrukkingsparameter volgens Bjerrum, Calpha trap 3 | HD4: Samendrukkingsparameter volgens Bjerrum, Calpha trap 4 | HE4: Samendrukkingsparameter volgens Bjerrum, Calpha trap 5 | HF4: Samendrukkingsparameter volgens Bjerrum, Calpha trap 6 | HG4: Samendrukkingsparameter volgens Bjerrum, Calpha trap 7 | HH4: Samendrukkingsparameter volgens Bjerrum, Calpha trap 8 | HI4: Samendrukkingsparameter volgens Bjerrum, Calpha trap 9 | HJ4: Samendrukkingsparameter volgens Bjerrum, Calpha trap 10 | HK4: NEN Bjerrum Vo | HL4: Samendrukkingsparameter volgens Koppejan, grensspanning | HM4: Samendrukkingsparameter volgens Koppejan, rek bij de grensspanning | HN4: Samendrukkingsparameter volgens Koppejan, C waarde conform NEN5118 | HO4: Samendrukkingsparameter volgens Koppejan, C' waarde conform NEN5118 | HP4: Samendrukkingsparameter volgens Koppejan, C' waarde conform NEN5118, trap 2-3 | HQ4: Samendrukkingsparameter volgens Koppejan, C' waarde conform NEN5118, trap 3-4 | HR4: Samendrukkingsparameter volgens Koppejan, C' waarde conform NEN5118, trap 4-5 | HS4: Samendrukkingsparameter volgens Koppejan, C' waarde conform NEN5118, trap 5-6 | HT4: Samendrukkingsparameter volgens Koppejan, C' waarde conform NEN5118, trap 6-7 | HU4: Samendrukkingsparameter volgens Koppejan, C' waarde conform NEN5118, trap 7-8 | HV4: Samendrukkingsparameter volgens Koppejan, C' waarde conform NEN5118, trap 8-9 | HW4: Samendrukkingsparameter volgens Koppejan, Cp waarde conform NEN5118 | HX4: Samendrukkingsparameter volgens Koppejan, C'p waarde conform NEN5118 | HY4: Samendrukkingsparameter volgens Koppejan, Cp' waarde conform NEN5118, trap 2-3 | HZ4: Samendrukkingsparameter volgens Koppejan, Cp' waarde conform NEN5118, trap 3-4 | IA4: Samendrukkingsparameter volgens Koppejan, Cp' waarde conform NEN5118, trap 4-5 | IB4: Samendrukkingsparameter volgens Koppejan, Cp' waarde conform NEN5118, trap 5-6 | IC4: Samendrukkingsparameter volgens Koppejan, Cp' waarde conform NEN5118, trap 6-7 | ID4: Samendrukkingsparameter volgens Koppejan, Cp' waarde conform NEN5118, trap 7-8 | IE4: Samendrukkingsparameter volgens Koppejan, Cp' waarde conform NEN5118, trap 8-9 | IF4: Samendrukkingsparameter volgens Koppejan, Cs waarde conform NEN5118 | IG4: Samendrukkingsparameter volgens Koppejan, C's waarde conform NEN5118 | IH4: Samendrukkingsparameter volgens Koppejan, Cs' waarde conform NEN5118, trap 2-3 | II4: Samendrukkingsparameter volgens Koppejan, Cs' waarde conform NEN5118, trap 3-4 | IJ4: Samendrukkingsparameter volgens Koppejan, Cs' waarde conform NEN5118, trap 4-5 | IK4: Samendrukkingsparameter volgens Koppejan, Cs' waarde conform NEN5118, trap 5-6 | IL4: Samendrukkingsparameter volgens Koppejan, Cs' waarde conform NEN5118, trap 6-7 | IM4: Samendrukkingsparameter volgens Koppejan, Cs' waarde conform NEN5118, trap 7-8 | IN4: Samendrukkingsparameter volgens Koppejan, Cs' waarde conform NEN5118, trap 8-9 | IO4: Samendrukkingsparameter volgens Isotache, a-waarde | IP4: Samendrukkingsparameter volgens Isotache, b-waarde | IQ4: Samendrukkingsparameter volgens Isotache, c-waarde | IR4: Samendrukkingsparameter volgens Isotache, grensspanning A | IS4: Samendrukkingsparameter volgens Isotache, rek bij grensspanning A | IT4: Samendrukkingsparameter volgens Isotache, bovengrens van de grensspanning B | IU4: Waarde van de bepaling volgens Casagrande van de Cv; 10 (m2/s) bij trap 2 | IV4: Waarde van de bepaling volgens Casagrande van de Cv; 10 (m2/s) bij trap 3 | IW4: Waarde van de bepaling volgens Casagrande van de Cv; 10 (m2/s) bij trap 4 | IX4: Waarde van de bepaling volgens Casagrande van de Cv; 10 (m2/s) bij trap 5 | IY4: Waarde van de bepaling volgens Casagrande van de Cv; 10 (m2/s) bij trap 6 | IZ4: Waarde van de bepaling volgens Casagrande van de Cv; 10 (m2/s) bij trap 7 | JA4: Waarde van de bepaling volgens Casagrande van de Cv; 10 (m2/s) bij trap 8 | JB4: Waarde van de bepaling volgens Casagrande van de Cv; 10 (m2/s) bij trap 9 | JC4: Waarde van de bepaling volgens Casagrande van de k10 (m/s) bij trap 2 | JD4: Waarde van de bepaling volgens Casagrande van de k10 (m/s) bij trap 3 | JE4: Waarde van de bepaling volgens Casagrande van de k10 (m/s) bij trap 4 | JF4: Waarde van de bepaling volgens Casagrande van de k10 (m/s) bij trap 5 | JG4: Waarde van de bepaling volgens Casagrande van de k10 (m/s) bij trap 6 | JH4: Waarde van de bepaling volgens Casagrande van de k10 (m/s) bij trap 7 | JI4: Waarde van de bepaling volgens Casagrande van de k10 (m/s) bij trap 8 | JJ4: Waarde van de bepaling volgens Casagrande van de k10 (m/s) bij trap 9 | JK4: Waarde van de bepaling volgens Casagrande van de mv (1/MPa) bij trap 2 | JL4: Waarde van de bepaling volgens Casagrande van de mv (1/MPa) bij trap 3 | JM4: Waarde van de bepaling volgens Casagrande van de mv (1/MPa) bij trap 4 | JN4: Waarde van de bepaling volgens Casagrande van de mv (1/MPa) bij trap 5 | JO4: Waarde van de bepaling volgens Casagrande van de mv (1/MPa) bij trap 6 | JP4: Waarde van de bepaling volgens Casagrande van de mv (1/MPa) bij trap 7 | JQ4: Waarde van de bepaling volgens Casagrande van de mv (1/MPa) bij trap 8 | JR4: Waarde van de bepaling volgens Casagrande van de mv (1/MPa) bij trap 9 | JS4: spanning bij cv;2 | JT4: spanning bij cv;3 | JU4: spanning bij cv;4 | JV4: spanning bij cv;5 | JW4: spanning bij cv;6 | JX4: spanning bij cv;7 | JY4: spanning bij cv;8 | JZ4: spanning bij cv;9 | KA4: Waarde van de bepaling volgens Taylor van de Cv; 10 (m2/s) bij trap 2 | KB4: Waarde van de bepaling volgens Taylor van de Cv; 10 (m2/s) bij trap 3 | KC4: Waarde van de bepaling volgens Taylor van de Cv; 10 (m2/s) bij trap 4 | KD4: Waarde van de bepaling volgens Taylor van de Cv; 10 (m2/s) bij trap 5 | KE4: Waarde van de bepaling volgens Taylor van de Cv; 10 (m2/s) bij trap 6 | KF4: Waarde van de bepaling volgens Taylor van de Cv; 10 (m2/s) bij trap 7 | KG4: Waarde van de bepaling volgens Taylor van de Cv; 10 (m2/s) bij trap 8 | KH4: Waarde van de bepaling volgens Taylor van de Cv; 10 (m2/s) bij trap 9 | KI4: Waarde van de bepaling volgens Taylor van de k10 (m/s) bij trap 2 | KJ4: Waarde van de bepaling volgens Taylor van de k10 (m/s) bij trap 3 | KK4: Waarde van de bepaling volgens Taylor van de k10 (m/s) bij trap 4 | KL4: Waarde van de bepaling volgens Taylor van de k10 (m/s) bij trap 5 | KM4: Waarde van de bepaling volgens Taylor van de k10 (m/s) bij trap 6 | KN4: Waarde van de bepaling volgens Taylor van de k10 (m/s) bij trap 7 | KO4: Waarde van de bepaling volgens Taylor van de k10 (m/s) bij trap 8 | KP4: Waarde van de bepaling volgens Taylor van de k10 (m/s) bij trap 9 | KQ4: Waarde van de bepaling volgens Taylor van de mv (1/MPa) bij trap 2 | KR4: Waarde van de bepaling volgens Taylor van de mv (1/MPa) bij trap 3 | KS4: Waarde van de bepaling volgens Taylor van de mv (1/MPa) bij trap 4 | KT4: Waarde van de bepaling volgens Taylor van de mv (1/MPa) bij trap 5 | KU4: Waarde van de bepaling volgens Taylor van de mv (1/MPa) bij trap 6 | KV4: Waarde van de bepaling volgens Taylor van de mv (1/MPa) bij trap 7 | KW4: Waarde van de bepaling volgens Taylor van de mv (1/MPa) bij trap 8 | KX4: Waarde van de bepaling volgens Taylor van de mv (1/MPa) bij trap 9 | KY4: spanning bij cv;2 | KZ4: spanning bij cv;3 | LA4: spanning bij cv;4 | LB4: spanning bij cv;5 | LC4: spanning bij cv;6 | LD4: spanning bij cv;7 | LE4: spanning bij cv;8 | LF4: spanning bij cv;9 | LG4: Bestandnaam van de pdf waarin de DSS-proef is gerapporteerd | LH4: Bestandsnaam van de file waarin het spanningspad conform het STOWA-format is opgenomen | LI4: Monsternummering van de Direct Simple Shear-proef | LJ4: Laboratorium waar de Direct Simple Shear-proef is uitgevoerd | LK4: Bij de uitvoering van de DSS-proef aangehouden normen | LL4: Datum waarop de DSS-proef is uitgevoerd | LM4: Classificatie van de grond conform de gehanteerde norm | LN4: Beschrijving van de bijzondere bestanddelen of secundaire of tertiaire fracties | LO4: Niveau van het monster van de Direct Simple Shear-proef | LP4: Inschatting van de terreinspanning (= effectieve verticale spanning) op het niveau van het beproefde monster | LQ4: Resultaat van de bepaling van het initiele volumieke gewicht conform NEN5110/5111 voor uitvoering van de proef | LR4: Resultaat van de bepaling van het droge volumieke gewicht conform NEN5110/5111 voor uitvoering van de proef | LS4: Resultaat van de bepaling van het initiele watergehalte conform NEN5112/5113 voor uitvoering van de proef | LT4: Resultaat van de bepaling van het initiele watergehalte conform NEN5112/5113 na uitvoering van de proef | LU4: Resultaat van de bepaling van het verzadigingsgraad voor uitvoering van de proef conform ... | LV4: Resultaat van de bepaling van het poriengetal voor uitvoering van de proef conform ... | LW4: Het poriengetal van het proefstuk na consolideren | LX4: Resultaat van de bepaling van het specifieke massa voor uitvoering van de proef conform ... | LY4: Maximum temperatuur in het laboratorium gedurende de uitvoering van de proef | LZ4: Minimum temperatuur in het laboratorium gedurende de uitvoering van de proef | MA4: Diameter van het proefstuk dat in het DSS-apparaat is beproefd voor beproeving | MB4: Hoogte van het proefstuk dat in het DSS-apparaat is beproefd voor beproeving | MC4: De hoogte van het proefstuk na consolideren | MD4: Beschrijving van de bij de uitwerking van de proef uitgevoerde correcties | ME4: Uitvoeringswijze van de proef: [constante hoogte, constante bovenbelasting] Shansep methode (bij consolidatie belasten tot voorbij de grensspanning en vervolgens ontlasten): [wel of niet toegepast] | MF4: Effectieve verticale spanning bij de maximale consolidatiespanning tijdens consolideren (gemeten waarde) / (alleen van toepassing bij Shansep methode) | MG4: Effectieve verticale spanning bij de consolidatiespanning aan het eind van het consolideren, is gelijk aan spanning bij begin belasten (gemeten waarde) | MH4: OCR bepaald op basis van de maximale consolidatie spanning (indien groter dan de grensspanning) te delen door de spanning waarbij het monster is beproefd | MI4: Axiale rek bij het einde van de consolidatie | MJ4: Aantal belasttrappen tijdens het consolideren | MK4: De duur van de consolidatiefase | ML4: De afschuifsnelheid tijdens de proef in %/uur | MM4: De afschuifsnelheid tijdens de proef in mm/uur | MN4: De normaalspanning (sigma) bij 2% rek | MO4: De schuifspanning (tau) bij 2% rek | MP4: De normaalspanning (sigma) bij 5% rek | MQ4: De schuifspanning (tau) bij 5% rek | MR4: De normaalspanning (sigma) bij 10% rek | MS4: De schuifspanning (tau) bij 10% rek | MT4: De normaalspanning (sigma) bij 15% rek | MU4: De schuifspanning (tau) bij 15% rek | MV4: De normaalspanning (sigma) bij 20% rek | MW4: De schuifspanning (tau) bij 20% rek | MX4: De normaalspanning (sigma) bij de maximale schuifspanning (bij tau_piek) | MY4: De maximale schuifspanning (tau_piek) | MZ4: De rek op het moment dat de schuifspanning maximaal is | NA4: De axiale spanning (sigma) bij het einde van de proef (bij tau_eind) | NB4: De schuifspanning (tau_eind) bij het einde van de proef | NC4: De rek bij het einde van de proef | ND4: Databaseveld komt te vervallen | NE4: Databaseveld komt te vervallen | NF4: Databaseveld komt te vervallen | NG4: De schuifmodulus G50. De G50 wordt bepaald door de helling van de tau-rek curve op het moment dat de halve pieksterkte wordt gehaald. | NH4: Bestandnaam van de pdf waarin de triaxiaal-proef is gerapporteerd | NI4: Bestandsnaam van de file waarin het spanningspad conform het STOWA-format is opgenomen | NJ4: Monsternummering van de triaxiaal-proef | NK4: Laboratorium waar de triaxiaal-proef is uitgevoerd | NL4: Bij de uitvoering van de triaxiaal-proef aangehouden normen | NM4: Datum waarop de triaxiaal-proef is uitgevoerd | NN4: Classificatie van de grond conform de gehanteerde norm | NO4: Beschrijving van de bijzondere bestanddelen of secundaire of tertiaire fracties | NP4: Niveau van het monster van de triaxiaal-proef | NQ4: Inschatting van de terreinspanning (= effectieve verticale spanning) op het niveau van het beproefde monster | NR4: Resultaat van de bepaling van het initiele volumieke gewicht conform NEN5110/5111 voor uitvoering van de proef | NS4: Resultaat van de bepaling van het droge volumieke gewicht conform NEN5110/5111 voor uitvoering van de proef | NT4: Resultaat van de bepaling van het initiele watergehalte conform NEN5112/5113 na uitvoering van de proef | NU4: Resultaat van de bepaling van het initiele watergehalte conform NEN5112/5113 voor uitvoering van de proef | NV4: Resultaat van de bepaling van het verzadigingsgraad voor uitvoering van de proef conform ... | NW4: Resultaat van de bepaling van het poriengetal voor uitvoering van de proef conform ... | NX4: Resultaat van de bepaling van het specifieke massa voor uitvoering van de proef conform ... | NY4: Maximum temperatuur in het laboratorium gedurende de uitvoering van de proef | NZ4: Minimum temperatuur in het laboratorium gedurende de uitvoering van de proef | OA4: Diameter van het proefstuk dat in het triaxiaal-apparaat is beproefd voor beproeving | OB4: Hoogte van het proefstuk dat in het triaxiaal-apparaat is beproefd voor beproeving | OC4: Type triaxiaalproef [gedraineerd, ongedraineerd, geconsolideerd, niet geconsolideerd] | OD4: Manier/methode waarop membraam correctie is toegepast | OE4: Beschrijving vna de aangehouden overige correcties | OF4: Backpressure | OG4: Consolidatiewijze: [volledig isotroop, volledig anisotroop, eerst isotroop en vervolgens anisotroop] Shansep methode (bij consolidatie belasten tot voorbij de grensspanning en vervolgens ontlasten): [wel of niet toegepast] | OH4: Aangehouden spanningsverhouding bij het stopcriterium (K) | OI4: Stopcriterium in de consolidatiefase | OJ4: Gemiddelde effectieve normaalspanning aan het eind van de isotrope consolidatiefase | OK4: Schuifspanning aan het eind van de isotrope consolidatiefase. Deze is 0 kPa bij isotrope consolidatie | OL4: Gemiddelde effectieve spanning behorende bij de maximale consolidatiespanning (alleen van toepassing bij Shansep methode) | OM4: Schuifspanning behorende bij de maximale consolidatiespanning (alleen van toepassing bij Shansep methode) | ON4: Gemiddeld effectieve normaalspanning behorende bij de eind consolidatiespanning s' = 0,5 * (sigma_1' + sigma_3') | OO4: Schuifspanning behorende bij de eind consolidatiespanning | OP4: Overconsolidatieratio bepaald op basis van de maximale consolidatiespanning en de eind consolidatiespanning | OQ4: Bereikte axiale rek tijdens de consolidatiefase | OR4: Bereikte volumerek tijdens de consolidatiefase | OS4: Stopcriterium in de afschuiffase | OT4: Aangehouden axiale reksnelheid tijdens het afschuiven | OU4: Gemiddelde effectieve normaalspanning bij 2% rek | OV4: Schuifspanning bij 2% rek | OW4: Gemiddelde effectieve normaalspanning bij 5% rek | OX4: Schuifspanning bij 5% rek | OY4: Gemiddelde effectieve normaalspanning bij 15% rek | OZ4: Schuifspanning bij 15% rek | PA4: Gemiddelde effectieve normaalspanning bij de maximale schuifspanning (T_PIEK) | PB4: Maximale schuifspanning (T_PIEK) | PC4: Rek bij de maximale schuifspanning (T_PIEK) | PD4: Gemiddelde effectieve normaalspanning bij de eind schuifspanning / eindrek (T_EIND) | PE4: Eind schuifspanning bij de eindrek (T_EIND) | PF4: Eindrek behorend bij de eind schuifspanning (T_EIND) | PG4: Ongedraineerde elasticiteit Eundrained;50%. Bepaald bij 50% van de maximale schuifspanning [T_50% = (T_0:start schuifspanning + T_PIEK:maximale schuifspanning) / 2] | PH4: Rek behorend bij de ongedraineerde elasticiteit Eundrained;50% | PI4: De skempton-A factor bepaald op basis van de wateroverspanning tijdens afschuiffase (bij T_PIEK) | PJ4: koppeling pdf(hyperlink) | PK4: Bestandsnaam van de file waarin het spanningspad conform het STOWA-format is opgenomen | PL4: Monster-id | PM4: Naam laboratorium +plaats | PN4: Consolidatie-spanning | PO4: e b;50max deviator | PP4: Eundr, 50max deviator | PQ4: s' 1e trap2% rek | PR4: s' 2e trap2% rek | PS4: s' 3e trap2% rek | PT4: t 1e trap2% rek | PU4: t 2e trap2% rek | PV4: t 3e trap2% rek | PW4: c'2% rek | PX4: f'2% rek | PY4: s' 1e trap5% rek | PZ4: s' 2e trap5% rek | QA4: s' 3e trap5% rek | QB4: t 1e trap5% rek | QC4: t 2e trap5% rek | QD4: t 3e trap5% rek | QE4: c'5% rek | QF4: f'5% rek | QG4: koppeling pdf(hyperlink) | QH4: Bestandsnaam van de file waarin het spanningspad conform het STOWA-format is opgenomen | QI4: phi'1 | QJ4: c'1 | QK4: phi'2 | QL4: c'2 | QM4: phi'3 | QN4: c'3 | QO4: phi'4 | QP4: c'4 | QQ4: phi'5 | QR4: c'5 | QS4: eindspanning
