Workbook

Sheet Dbase5_0
A2: Algemene kenmerken | V2: Kenmerken van de boring | AI2: Monster | AQ2: Classificatie | BP2: Atterbergsche grenzen | BT2: Veenclassificatie | CE2: Korrelverdeling zeefproef en fractieverdeling | DM2: Kenmerken van de sondering | EA2: Constant rate of strain proeven (CRS) | FK2: Samendrukkingsproeven | LG2: DSS-proeven | NH2: Triaxiaalproeven single stage | PJ2: Triaxiaalproeven multistage | QG2: Beschrijving proefresultaten | QM2: controle berekening terreinspanning | QT2: Analyse op data met de proevenverzameling tool
A4: Boring + monster nummer ID (gebruikt voor identificatie) | B4: Algemeen regelnummer | C4: Classificatie proeven uitgevoerd | D4: Veen classificatie uitgevoerd | E4: Korrel verdeling uitgevoerd | F4: Sondering uitgevoerd | G4: CRS-proef uitgevoerd | H4: Samendrukkings proef uitgevoerd | I4: DSS-proef uitgevoerd | J4: Triaxiaal proef uitgevoerd | K4: Opdrachtgever | L4: Projectnaam | M4: Projectnummer | N4: naam Polder Dijk | O4: Referentie | P4: Regio | Q4: Type waterkering | R4: Aanlegjaar | S4: Bodemkaart | T4: Geologie | U4: Filenaam Geot Profiel | V4: Xid | W4: Yid | X4: Maaiveldniveau | Y4: Nummer | Z4: Positie | AA4: Datum | AB4: Filenaam PDF | AC4: Filenaam GEF | AD4: Bedrijf | AE4: Boormeester | AF4: Methode | AG4: Opname GWS | AH4: GLG | AI4: Id | AJ4: Steekmethode | AK4: Opslagwijze | AL4: Niveau NAP vanaf | AM4: Niveau NAP tot | AN4: Niveau mv vanaf | AO4: Niveau mv tot | AP4: Totaal volumegewicht monsterbus | AQ4: Filenaam PDF | AR4: Filenaam Digitaal | AS4: Monsterid | AT4: Laboratorium classificatie + veenclassificatie | AU4: Normen | AV4: Datum | AW4: Classificatie grond | AX4: Beschrijving bijzondere bestanddelen of secundaire of tertiaire fracties | AY4: Monsterniveau | AZ4: Volumegewicht nat | BA4: Volumegewicht droog | BB4: Watergehalte | BC4: Porositeit | BD4: Poriengetal | BE4: Verzadigingsgraad | BF4: Volumegewicht Verzadigd | BG4: Specifieke massa Inschatting | BH4: Specifieke massa | BI4: Gloeiverlies | BJ4: Kalkgehalte | BK4: Pocketpenetro | BL4: Torvane | BM4: Fallinghead K10 | BN4: Constanthead K10 | BO4: Opmerking | BP4: Vloeigrens Cas | BQ4: Uitrolgrens | BR4: Plasticiteitsindex | BS4: Consistentieindex | BT4: Filenaam PDF | BU4: Filenaam Digitaal | BV4: Hoofdnaam | BW4: Botanisch | BX4: Verweringsgraad | BY4: Watergehalte | BZ4: Fijnevezels | CA4: Grovevezels | CB4: Hout | CC4: Gloeiverlies | CD4: Asgehalte | CE4: Filenaam PDF | CF4: Filenaam GEF | CG4: Monsterid | CH4: Laboratorium | CI4: Normen | CJ4: Datum | CK4: Classificatie grond | CL4: Beschrijving bijzondere bestanddelen of secundaire of tertiaire fracties | CM4: Mediaan Zandfractie | CN4: Mediaan Allefracties | CO4: Grind% | CP4: Zand% | CQ4: Silt% | CR4: %grind< 63 mm | CS4: %grind< 31,5 mm | CT4: %grind< 16 mm | CU4: %grind< 8 mm | CV4: %grind< 4 mm | CW4: %zand< 2 mm | CX4: %zand< 1 mm | CY4: %zand< 0,5 mm | CZ4: %zand< 250 μm | DA4: %zand< 180 μm | DB4: %zand< 125 μm | DC4: %silt< 63 μm | DD4: %silt< 32 μm | DE4: %silt< 20 μm | DF4: %slib< 16 μm | DG4: %lutum< 2 μm | DH4: D70 | DI4: D60 | DJ4: D50 | DK4: D10 | DL4: Cu Zand | DM4: Filenaam PDF | DN4: Filenaam GEF | DO4: Niveau | DP4: Trajectlengte gemiddeld | DQ4: Gemeten gemiddelde conusweerstand qc | DR4: Gemeten gemiddelde wrijvingsweerstand fs | DS4: Wrijvingsgetal gemiddeld Rf | DT4: Waterspanning gemiddeld u2 | DU4: Netto conusweerstand = qnet = qt - σv0 | DV4: Conusweerstand correctie gem. watersp. qt | DW4: Verticale grondspanning σv0 | DX4: Sonderingklasse 1 of 2 | DY4: netto oppervlakteverhoudingscoëfficiënt van de conus = a | DZ4: conusweerstand qc ball weerstandbolsonde | EA4: Filenaam PDF | EB4: Filenaam Spanningspad | EC4: Monsterid | ED4: Laboratorium | EE4: Norm | EF4: Datum | EG4: Classificatie grond | EH4: Beschrijving bijzondere bestanddelen of secundaire of tertiaire fracties | EI4: Monsterniveau | EJ4: Terreinspanning | EK4: Volumegewicht nat | EL4: Volumegewicht droog | EM4: Watergehalte voor | EN4: Watergehalte na proef | EO4: Verzadiging | EP4: Temperatuur proef max | EQ4: Temperatuur proef min | ER4: Proefstukdiameter voor | ES4: Proefstukhoogte voor | ET4: Proefstukhoogte na verzadiging | EU4: Proefstukhoogte na proef | EV4: Reksnelheid belasten | EW4: Reksnelheid ontlasten | EX4: Relaxatieduur | EY4: Eff spanning start relaxatie | EZ4: Eff spanning eind relaxatie | FA4: Eff vert spanning start ontlasten | FB4: Eff vert spanning eind Ontlasten | FC4: Eff vert spanning eind proef | FD4: Max rel wateroverspanning proef | FE4: Grensspanning A | FF4: Rek bij grensspanning A | FG4: Bovengrens grensspanning B | FH4: Isotache A | FI4: Isotache B | FJ4: Isotache C | FK4: Filenaam PDF | FL4: Filenaam spanningspad | FM4: Monsterid | FN4: Laboratorium | FO4: Norm | FP4: Datum | FQ4: Classificatie grond | FR4: Beschrijving bijzondere bestanddelen of secundaire of tertiaire fracties | FS4: Monsterniveau | FT4: Terreinspanning | FU4: Volumegewicht nat | FV4: Volumegewicht droog | FW4: Watergehalte initieel | FX4: Watergehalte na proef | FY4: Poriengetal | FZ4: Max temperatuur proef | GA4: Min temperatuur proef | GB4: Belast ontlaststappen | GC4: Typeproef | GD4: Bjerrum grensspanning | GE4: Bjerrum rek bij grensspanning | GF4: Bjerrum Cc | GG4: Bjerrum Cc Trap1 2 | GH4: Bjerrum Cc Trap2 3 | GI4: Bjerrum Cc Trap3 4 | GJ4: Bjerrum Cc Trap4 5 | GK4: Bjerrum Cc Trap5 6 | GL4: Bjerrum Cc Trap6 7 | GM4: Bjerrum Cc Trap7 8 | GN4: Bjerrum Cc Trap8 9 | GO4: Bjerrum Cc Trap9 10 | GP4: Bjerrum Cr | GQ4: Bjerrum Cr Trap1 2 | GR4: Bjerrum Cr Trap2 3 | GS4: Bjerrum Cr Trap3 4 | GT4: Bjerrum Cr Trap4 5 | GU4: Bjerrum Cr Trap5 6 | GV4: Bjerrum Cr Trap6 7 | GW4: Bjerrum Cr Trap7 8 | GX4: Bjerrum Sr Trap8 9 | GY4: Bjerrum Rr Trap9 10 | GZ4: Bjerrum Calpha | HA4: Bjerrum Calpha Trap1 | HB4: Bjerrum Calpha Trap2 | HC4: Bjerrum Calpha Trap3 | HD4: Bjerrum Calpha Trap4 | HE4: Bjerrum Calpha Trap5 | HF4: Bjerrum Calpha Trap6 | HG4: Bjerrum Calpha Trap7 | HH4: Bjerrum Calpha Trap8 | HI4: Bjerrum Calpha Trap9 | HJ4: Bjerrum Calpha Trap10 | HK4: Bjerrum V0 | HL4: Koppejan Grensspanning | HM4: Koppejan Rek bij Grensspanning | HN4: Koppejan C | HO4: Koppejan C' | HP4: Koppejan C Trap2 3 | HQ4: Koppejan C Trap3 4 | HR4: Koppejan C Trap4 5 | HS4: Koppejan C Trap5 6 | HT4: Koppejan C Trap6 7 | HU4: Koppejan C Trap7 8 | HV4: Koppejan C Trap8 9 | HW4: Koppejan Cp | HX4: Koppejan C'p | HY4: Koppejan Cp Trap2 3 | HZ4: Koppejan Cp Trap3 4 | IA4: Koppejan Cp Trap4 5 | IB4: Koppejan Cp Trap5 6 | IC4: Koppejan Cp Trap6 7 | ID4: Koppejan Cp Trap7 8 | IE4: Koppejan Cp Trap8 9 | IF4: Koppejan Cs | IG4: Koppejan C's | IH4: Koppejan Cs Trap2 3 | II4: Koppejan Cs Trap3 4 | IJ4: Koppejan Cs Trap4 5 | IK4: Koppejan Cs Trap5 6 | IL4: Koppejan Cs Trap6 7 | IM4: Koppejan Cs Trap7 8 | IN4: Koppejan Cs Trap8 9 | IO4: Isotache A | IP4: Isotache B | IQ4: Isotache C | IR4: Isotache Grensspanning A | IS4: Isotache Rek bij Grensspanning A | IT4: Isotache Bovengrens Grensspanning B | IU4: Casagrande Cv10 Trap2 | IV4: Casagrande Cv10 Trap3 | IW4: Casagrande Cv10 Trap4 | IX4: Casagrande Cv10 Trap5 | IY4: Casagrande Cv10 Trap6 | IZ4: Casagrande Cv10 Trap7 | JA4: Casagrande Cv10 Trap8 | JB4: Casagrande Cv10 Trap9 | JC4: Casagrande K10 Trap2 | JD4: Casagrande K10 Trap3 | JE4: Casagrande K10 Trap4 | JF4: Casagrande K10 Trap5 | JG4: Casagrande K10 Trap6 | JH4: Casagrande K10 Trap7 | JI4: Casagrande K10 Trap8 | JJ4: Casagrande K10 Trap9 | JK4: Casagrande Mv Trap2 | JL4: Casagrande Mv Trap3 | JM4: Casagrande Mv Trap4 | JN4: Casagrande Mv Trap5 | JO4: Casagrande Mv Trap6 | JP4: Casagrande Mv Trap7 | JQ4: Casagrande Mv Trap8 | JR4: Casagrande Mv Trap9 | JS4: Casagrande Spanning Cv10 Trap2 | JT4: Casagrande Spanning Cv10 Trap3 | JU4: Casagrande Spanning Cv10 Trap4 | JV4: Casagrande Spanning Cv10 Trap5 | JW4: Casagrande Spanning Cv10 Trap6 | JX4: Casagrande Spanning Cv10 Trap7 | JY4: Casagrande Spanning Cv10 Trap8 | JZ4: Casagrande Spanning Cv10 Trap9 | KA4: Taylor Cv10 Trap2 | KB4: Taylor Cv10 Trap3 | KC4: Taylor Cv10 Trap4 | KD4: Taylor Cv10 Trap5 | KE4: Taylor Cv10 Trap6 | KF4: Taylor Cv10 Trap7 | KG4: Taylor Cv10 Trap8 | KH4: Taylor Cv10 Trap9 | KI4: Taylor K10 Trap2 | KJ4: Taylor K10 Trap3 | KK4: Taylor K10 Trap4 | KL4: Taylor K10 Trap5 | KM4: Taylor K10 Trap6 | KN4: Taylor K10 Trap7 | KO4: Taylor K10 Trap8 | KP4: Taylor K10 Trap9 | KQ4: Taylor Mv Trap2 | KR4: Taylor Mv Trap3 | KS4: Taylor Mv Trap4 | KT4: Taylor Mv Trap5 | KU4: Taylor Mv Trap6 | KV4: Taylor Mv Trap7 | KW4: Taylor Mv Trap8 | KX4: Taylor Mv Trap9 | KY4: Taylor Spanning Cv10 Trap2 | KZ4: Taylor Spanning Cv10 Trap3 | LA4: Taylor Spanning Cv10 Trap4 | LB4: Taylor Spanning Cv10 Trap5 | LC4: Taylor Spanning Cv10 Trap6 | LD4: Taylor Spanning Cv10 Trap7 | LE4: Taylor Spanning Cv10 Trap8 | LF4: Taylor Spanning Cv10 Trap9 | LG4: Filenaam PDF | LH4: Filenaam Spanningspad | LI4: Monsterid | LJ4: Laboratorium | LK4: Norm | LL4: Datum | LM4: Classificatie grond | LN4: Beschrijving bijzondere bestanddelen of secundaire of tertiaire fracties | LO4: Monsterniveau | LP4: Terreinspanning | LQ4: Volumegewicht nat | LR4: Volumegewicht droog | LS4: Watergehalte voor | LT4: Watergehalte na proef | LU4: Verzadiginggraad voor | LV4: Poriengetal voor | LW4: Poriengetal einde consolidatie | LX4: Specifieke massa | LY4: Temperatuur proef max | LZ4: Temperatuur proef min | MA4: proefstukdiameter voor | MB4: proefstukhoogte voor | MC4: proefstukhoogte na consolidatie | MD4: Uitgevoerde Correcties | ME4: Uitvoeringswijze | MF4: Effectieve vertikale spanning - max consolidatie | MG4: Effectieve vertikale spanning - einde consolidatie | MH4: Overconsolidatieratio monster | MI4: Axiale rek einde consolidatie | MJ4: Belastingsstappen consolidatie | MK4: Duur consolidatie | ML4: Afschuifsnelheid %/uur | MM4: Afschuifsnelheid mm/uur | MN4: Normaalspanning σ'n bij 2% rek | MO4: Schuifspanning τ bij 2% rek | MP4: Normaalspanning σ'n bij 5% rek | MQ4: Schuifspanning τ bij 5% rek | MR4: Normaalspanning σ'n bij 10% rek | MS4: Schuifspanning τ bij 10% rek | MT4: Normaalspanning σ'n bij 15% rek | MU4: Schuifspanning τ bij 15% rek | MV4: Normaalspanning σ'n bij 20% rek | MW4: Schuifspanning τ bij 20% rek | MX4: Normaalspanning σ'n bij τ piek | MY4: Maximale schuifspanning τ piek | MZ4: Schuifrek bij max schuifspanning τ piek | NA4: Normaalspanning σ'n bij τ eind schuifrek | NB4: Schuifspanning τ bij eind schuifrek | NC4: Eind schuifrek | ND4: Databaseveld komt te vervallen | NE4: Databaseveld komt te vervallen | NF4: Databaseveld komt te vervallen | NG4: Schuifmodulus G50 | NH4: Filenaam PDF | NI4: Filenaam Spanningspad | NJ4: Monsterid | NK4: Laboratorium | NL4: Norm | NM4: Datum | NN4: Classificatie grond | NO4: Beschrijving bijzondere bestanddelen of secundaire of tertiaire fracties | NP4: Monsterniveau | NQ4: Terreinspanning σv' | NR4: Volumegewicht nat | NS4: Volumegewicht droog | NT4: Watergehalte na proef | NU4: Watergehalte voor | NV4: Verzadigingsgraad voor | NW4: Poriengetal voor | NX4: Specifieke massa | NY4: Temperatuur proef max | NZ4: Temperatuur proef min | OA4: proefstukdiameter voor | OB4: proefstukhoogte voor | OC4: Type proef | OD4: Membraancorrectie | OE4: Overigecorrecties | OF4: Backpressure | OG4: Consolidatiewijze | OH4: Spanningsverhouding stopcr K | OI4: Stopcriterium consolidatie | OJ4: Gem effectieve spanning σ' - isotrope consolidatie | OK4: Schuifspanning τ - isotrope consolidatie | OL4: Gem effectieve spanning σ' - max consolidatie | OM4: Schuifspanning τ - max consolidatie | ON4: Gem effectieve spanning σ' - einde consolidatie | OO4: Schuifspanning τ - einde consolidatie | OP4: OCR | OQ4: Axialerek consolidatie | OR4: Volumerek consolidatie | OS4: Stopcriterium Afschuiven | OT4: Axialereksnelheid Afschuiven | OU4: Gem eff spanning σ' bij 2% rek | OV4: Schuifspanning τ bij 2% rek | OW4: Gem eff spanning σ' bij 5% rek | OX4: Schuifspanning τ bij 5% rek | OY4: Gem eff spanning σ' bij 15% rek | OZ4: Schuifspanning τ bij 15% rek | PA4: Gem eff spanning σ' bij τ piek | PB4: Maximale schuifspanning τ piek | PC4: Schuifrek bij maximale schuifspanning τ piek | PD4: Gem eff spanning σ' bij τ eind schuifrek | PE4: Schuifspanning τ bij eind schuifrek | PF4: Eind schuifrek | PG4: E Undr50 | PH4: Rek bij E Undr50 | PI4: Skempton A | PJ4: Ms Filenaam PDF | PK4: Ms Filenaam Spanningspad | PL4: Ms Monsterid | PM4: Ms Laboratorium | PN4: Ms consolidatiespanning | PO4: Ms Rek bij E Undr50 | PP4: Ms E Undr50 | PQ4: Ms σ1' 2% | PR4: Ms σ2' 2% | PS4: Ms σ3' 2% | PT4: Ms τ1 2% | PU4: Ms τ2 2% | PV4: Ms τ3 2% | PW4: Ms C 2% | PX4: Ms Phi 2% | PY4: Ms σ1' 5% | PZ4: Ms σ2' 5% | QA4: Ms σ3' 5% | QB4: Ms τ1 5% | QC4: Ms τ2 5% | QD4: Ms τ3 5% | QE4: Ms C 5% | QF4: Ms Phi 5% | QG4: homogeen monster (ja/nee) | QH4: Bezwijkvorm (tonrond / schuifvlak) | QI4: kleur | QJ4: transitional soil? | QK4: score | QL4: opmerking | QM4: grondsoort bepaling POP | QN4: gemiddeld volumegewicht | QO4: - | QP4: - | QQ4: - | QR4: - | QS4: - | QT4: De naam van de verzameling (klei licht, klei zandig, veen, etc…) | QU4: - | QV4: Terreinspanning | QW4: Consolidatiespanning uit de TXT proef | QX4: Consolidatiespanning uit de DSS proef | QY4: Voorstel consolidatietype (TXT) | QZ4: Consolidatietype handmatig ingevoerd door gebruiker (TXT) | RA4: Consolidatietype waar mee gerekend wordt (TXT) | RB4: Voorstel consolidatietype (DSS) | RC4: Consolidatietype handmatig ingevoerd door gebruiker (DSS) | RD4: Consolidatietype waar mee gerekend wordt (DSS) | RE4: Grensspanning die volgt uit de proef | RF4: POP veld | RG4: POP veld gemiddeld | RH4: Voorstel grensspanning | RI4: Grensspanning handmatig ingevoerd door gebruiker | RJ4: Grensspanning waarmee gerekend wordt | RK4: OCR (TXT) | RL4: OCR (DSS)
A5: [-] | B5: [-] | C5: [-] | D5: [-] | E5: [-] | F5: [-] | G5: [-] | H5: [-] | I5: [-] | J5: [-] | K5: [-] | L5: [-] | M5: [-] | N5: [-] | O5: [-] | P5: [-] | Q5: [-] | R5: [-] | S5: [-] | T5: [-] | U5: [-] | V5: [m] | W5: [m] | X5: [m NAP] | Y5: [-] | Z5: [-] | AA5: [DD-MM-JJJJ] | AB5: [-] | AC5: [-] | AD5: [-] | AE5: [-] | AF5: [-] | AG5: [m NAP] | AH5: [m NAP] | AI5: [-] | AJ5: [-] | AK5: [-] | AL5: [m NAP] | AM5: [m NAP] | AN5: [m] | AO5: [m] | AP5: [kN/m3] | AQ5: [-] | AR5: [-] | AS5: [-] | AT5: [-] | AU5: [-] | AV5: [DD-MM-JJJJ] | AW5: [-] | AX5: [-] | AY5: [m NAP] | AZ5: [kN/m3] | BA5: [kN/m3] | BB5: [%] | BC5: [%] | BD5: [-] | BE5: [%] | BF5: [kN/m3] | BG5: [kg/m3] | BH5: [kg/m3] | BI5: [%] | BJ5: [%] | BK5: [kPa] | BL5: [kPa] | BM5: [m/s] | BN5: [m/s] | BO5: [-] | BP5: [%] | BQ5: [%] | BR5: [%] | BS5: [-] | BT5: [-] | BU5: [-] | BV5: [-] | BW5: [-] | BX5: [-] | BY5: [-] | BZ5: [-] | CA5: [-] | CB5: [-] | CC5: [%] | CD5: [%] | CE5: [-] | CF5: [-] | CG5: [-] | CH5: [-] | CI5: [-] | CJ5: [DD-MM-JJJJ] | CK5: [-] | CL5: [-] | CM5: [mu] | CN5: [mu] | CO5: [%] | CP5: [%] | CQ5: [%] | CR5: [%] | CS5: [%] | CT5: [%] | CU5: [%] | CV5: [%] | CW5: [%] | CX5: [%] | CY5: [%] | CZ5: [%] | DA5: [%] | DB5: [%] | DC5: [%] | DD5: [%] | DE5: [%] | DF5: [%] | DG5: [%] | DH5: [mu] | DI5: [mu] | DJ5: [mu] | DK5: [mu] | DL5: [-] | DM5: [-] | DN5: [-] | DO5: [m NAP] | DP5: [cm] | DQ5: [kPa] | DR5: [kPa] | DS5: [-] | DT5: [kPa] | DU5: [kPa] | DV5: [kPa] | DW5: [kPa] | DX5: [-] | DY5: [-] | DZ5: [kPa] | EA5: [-] | EB5: [-] | EC5: [-] | ED5: [-] | EE5: [-] | EF5: [DD-MM-JJJJ] | EG5: [-] | EH5: [-] | EI5: [m NAP] | EJ5: [kPa] | EK5: [kN/m3] | EL5: [kN/m3] | EM5: [%] | EN5: [%] | EO5: [kPa] | EP5: [°C] | EQ5: [°C] | ER5: [mm] | ES5: [mm] | ET5: [mm] | EU5: [mm] | EV5: [%/uur] | EW5: [%/uur] | EX5: [uur] | EY5: [kPa] | EZ5: [kPa] | FA5: [kPa] | FB5: [kPa] | FC5: [kPa] | FD5: [-] | FE5: [kPa] | FF5: [%] | FG5: [kPa] | FH5: [-] | FI5: [-] | FJ5: [-] | FK5: [-] | FL5: [-] | FM5: [-] | FN5: [-] | FO5: [-] | FP5: [DD-MM-JJJJ] | FQ5: [-] | FR5: [-] | FS5: [m NAP] | FT5: [kPa] | FU5: [kN/m3] | FV5: [kN/m3] | FW5: [%] | FX5: [%] | FY5: [-] | FZ5: [°C] | GA5: [°C] | GB5: [-] | GC5: [-] | GD5: [kPa] | GE5: [%] | GF5: [-] | GG5: [-] | GH5: [-] | GI5: [-] | GJ5: [-] | GK5: [-] | GL5: [-] | GM5: [-] | GN5: [-] | GO5: [-] | GP5: [-] | GQ5: [-] | GR5: [-] | GS5: [-] | GT5: [-] | GU5: [-] | GV5: [-] | GW5: [-] | GX5: [-] | GY5: [-] | GZ5: [-] | HA5: [-] | HB5: [-] | HC5: [-] | HD5: [-] | HE5: [-] | HF5: [-] | HG5: [-] | HH5: [-] | HI5: [-] | HJ5: [-] | HK5: [-] | HL5: [kPa] | HM5: [%] | HN5: [-] | HO5: [-] | HP5: [-] | HQ5: [-] | HR5: [-] | HS5: [-] | HT5: [-] | HU5: [-] | HV5: [-] | HW5: [-] | HX5: [-] | HY5: [-] | HZ5: [-] | IA5: [-] | IB5: [-] | IC5: [-] | ID5: [-] | IE5: [-] | IF5: [-] | IG5: [-] | IH5: [-] | II5: [-] | IJ5: [-] | IK5: [-] | IL5: [-] | IM5: [-] | IN5: [-] | IO5: [-] | IP5: [-] | IQ5: [-] | IR5: [kPa] | IS5: [%] | IT5: [kPa] | IU5: [m2/s] | IV5: [m2/s] | IW5: [m2/s] | IX5: [m2/s] | IY5: [m2/s] | IZ5: [m2/s] | JA5: [m2/s] | JB5: [m2/s] | JC5: [m/s] | JD5: [m/s] | JE5: [m/s] | JF5: [m/s] | JG5: [m/s] | JH5: [m/s] | JI5: [m/s] | JJ5: [m/s] | JK5: [1/MPa] | JL5: [1/MPa] | JM5: [1/MPa] | JN5: [1/MPa] | JO5: [1/MPa] | JP5: [1/MPa] | JQ5: [1/MPa] | JR5: [1/MPa] | JS5: [kPa] | JT5: [kPa] | JU5: [kPa] | JV5: [kPa] | JW5: [kPa] | JX5: [kPa] | JY5: [kPa] | JZ5: [kPa] | KA5: [m2/s] | KB5: [m2/s] | KC5: [m2/s] | KD5: [m2/s] | KE5: [m2/s] | KF5: [m2/s] | KG5: [m2/s] | KH5: [m2/s] | KI5: [m/s] | KJ5: [m/s] | KK5: [m/s] | KL5: [m/s] | KM5: [m/s] | KN5: [m/s] | KO5: [m/s] | KP5: [m/s] | KQ5: [1/MPa] | KR5: [1/MPa] | KS5: [1/MPa] | KT5: [1/MPa] | KU5: [1/MPa] | KV5: [1/MPa] | KW5: [1/MPa] | KX5: [1/MPa] | KY5: [kPa] | KZ5: [kPa] | LA5: [kPa] | LB5: [kPa] | LC5: [kPa] | LD5: [kPa] | LE5: [kPa] | LF5: [kPa] | LG5: [-] | LH5: [-] | LI5: [-] | LJ5: [-] | LK5: [-] | LL5: [DD-MM-JJJJ] | LM5: [-] | LN5: [-] | LO5: [m NAP] | LP5: [kPa] | LQ5: [kN/m3] | LR5: [kN/m3] | LS5: [%] | LT5: [%] | LU5: [%] | LV5: [-] | LW5: [-] | LX5: [kg/m3] | LY5: [°C] | LZ5: [°C] | MA5: [mm] | MB5: [mm] | MC5: [mm] | MD5: [-] | ME5: [-] | MF5: [kPa] | MG5: [kPa] | MH5: [-] | MI5: [%] | MJ5: [-] | MK5: [uur] | ML5: [%/uur] | MM5: [mm/uur] | MN5: [kPa] | MO5: [kPa] | MP5: [kPa] | MQ5: [kPa] | MR5: [kPa] | MS5: [kPa] | MT5: [kPa] | MU5: [kPa] | MV5: [kPa] | MW5: [kPa] | MX5: [kPa] | MY5: [kPa] | MZ5: [%] | NA5: [kPa] | NB5: [kPa] | NC5: [%] | ND5: [NVT] | NE5: [NVT] | NF5: [NVT] | NG5: [kPa] | NH5: [-] | NI5: [-] | NJ5: [-] | NK5: [-] | NL5: [-] | NM5: [DD-MM-JJJJ] | NN5: [-] | NO5: [-] | NP5: [m NAP] | NQ5: [kPa] | NR5: [kN/m3] | NS5: [kN/m3] | NT5: [%] | NU5: [%] | NV5: [%] | NW5: [-] | NX5: [kg/m3] | NY5: [°C] | NZ5: [°C] | OA5: [mm] | OB5: [mm] | OC5: [-] | OD5: [-] | OE5: [-] | OF5: [kPa] | OG5: [-] | OH5: [-] | OI5: [-] | OJ5: [kPa] | OK5: [kPa] | OL5: [kPa] | OM5: [kPa] | ON5: [kPa] | OO5: [kPa] | OP5: [-] | OQ5: [%] | OR5: [%] | OS5: [%] | OT5: [%/uur] | OU5: [kPa] | OV5: [kPa] | OW5: [kPa] | OX5: [kPa] | OY5: [kPa] | OZ5: [kPa] | PA5: [kPa] | PB5: [kPa] | PC5: [%] | PD5: [kPa] | PE5: [kPa] | PF5: [%] | PG5: [MPa] | PH5: [%] | PI5: [-] | PJ5: [-] | PK5: [-] | PL5: [-] | PM5: [-] | PN5: [kPa] | PO5: [%] | PP5: [MPa] | PQ5: [kPa] | PR5: [kPa] | PS5: [kPa] | PT5: [kPa] | PU5: [kPa] | PV5: [kPa] | PW5: [kPa] | PX5: [°] | PY5: [kPa] | PZ5: [kPa] | QA5: [kPa] | QB5: [kPa] | QC5: [kPa] | QD5: [kPa] | QE5: [kPa] | QF5: [°] | QG5: [-] | QH5: [-] | QI5: [°] | QJ5: [kPa] | QK5: [°] | QL5: [kPa] | QM5: [°] | QN5: [kPa] | QO5: [°] | QP5: [kPa] | QQ5: [°] | QR5: [kPa] | QS5: [kPa] | QT5: [-] | QU5: [-] | QV5: [kPa] | QW5: [kPa] | QX5: [kPa] | QY5: [-] | QZ5: [-] | RA5: [-] | RB5: [-] | RC5: [-] | RD5: [-] | RE5: [kPa] | RF5: [-] | RG5: [-] | RH5: [kPa] | RI5: [kPa] | RJ5: [kPa] | RK5: [-] | RL5: [-]
A7: ALG__BORING_MONSTERNR_ID | B7: ALG__REGEL | C7: ALG__CLASSIFICATIE | D7: ALG__VEENCLASSIFICATIE | E7: ALG__KORRELVERDELING | F7: ALG__SONDEERWAARDE | G7: ALG__CRS | H7: ALG__SAMENDRUKKING | I7: ALG__DSS | J7: ALG__TRIAXIAAL | K7: ALG_OPDRACHTGEVER | L7: ALG_PROJECTNAAM | M7: ALG_PROJECTNUMMER | N7: ALG_NAAM_POLDER_DIJK | O7: ALG_REFERENTIE | P7: ALG_REGIO | Q7: ALG_TYPE_WATERKERING | R7: ALG_AANLEGJAAR | S7: ALG_BODEMKAART | T7: ALG_GEOLOGIE | U7: ALG_FILENAAM_GEOT_PROFIEL | V7: BORING_XID | W7: BORING_YID | X7: BORING_MAAIVELDPEIL | Y7: BORING_NUMMER | Z7: BORING_POSITIE | AA7: BORING_DATUM | AB7: BORING_FILENAAM_PDF | AC7: BORING_FILENAAM_GEF | AD7: BORING_BEDRIJF | AE7: BORING_BOORMEESTER | AF7: BORING_METHODE | AG7: BORING_OPNAME_GWS | AH7: BORING_GLG | AI7: MONSTER_ID | AJ7: MONSTER_STEEKMETHODE | AK7: MONSTER_OPSLAGWIJZE | AL7: MONSTER_NIVEAU_NAP_VANAF | AM7: MONSTER_NIVEAU_NAP_TOT | AN7: MONSTER_NIVEAU_MV_VANAF | AO7: MONSTER_NIVEAU_MV_TOT | AP7: MONSTER_TOTAAL_VOLUMEGEWICHT | AQ7: CLAS_FILENAAM_PDF | AR7: CLAS_FILENAAM_DIGITAAL | AS7: CLAS_MONSTERID | AT7: CLAS_LABORATORIUM | AU7: CLAS_NORMEN | AV7: CLAS_DATUM | AW7: CLAS_GRONDSOORT | AX7: CLAS_OVERIGE_BESTANDDELEN | AY7: CLAS_MONSTERNIVEAU | AZ7: CLAS_VOLUMEGEWICHT_NAT | BA7: CLAS_VOLUMEGEWICHT_DRG | BB7: CLAS_WATERGEHALTE | BC7: CLAS_POROSITEIT | BD7: CLAS_PORIENGETAL | BE7: CLAS_VERZADIGINGSGRAAD | BF7: CLAS_VOLUMEGEWICHT_VERZADIGD | BG7: CLAS_SPECIFIEKE_MASSA_INSCHATTING | BH7: CLAS_SPECIFIEKE_MASSA | BI7: CLAS_GLOEIVERLIES | BJ7: CLAS_KALKGEHALTE | BK7: CLAS_POCKETPENETRO | BL7: CLAS_TORVANE | BM7: CLAS_FALLINGHEAD_K10 | BN7: CLAS_CONSTANTHEAD_K10 | BO7: CLAS_OPMERKING | BP7: CLAS_AT_VLOEIGRENS_CAS | BQ7: CLAS_AT_UITROLGRENS | BR7: CLAS_AT_PI | BS7: CLAS_AT_IC | BT7: CLAS_VN_FILENAAM_PDF | BU7: CLAS_VN_FILENAAM_DIGITAAL | BV7: CLAS_VN_HOOFDNAAM | BW7: CLAS_VN_BOTANISCH | BX7: CLAS_VN_VERWERINGSGRAAD | BY7: CLAS_VN_WATERGEHALTE | BZ7: CLAS_VN_FIJNEVEZELS | CA7: CLAS_VN_GROVEVEZELS | CB7: CLAS_VN_HOUT | CC7: CLAS_VN_GLOEIVERLIES | CD7: CLAS_VN_ASGEHALTE | CE7: KV_FILENAAM_PDF | CF7: KV_FILENAAM_GEF | CG7: KV_MONSTERID | CH7: KV_LABORATORIUM | CI7: KV_NORMEN | CJ7: KV_DATUM | CK7: KV_GRONDSOORT | CL7: KV_OVERIGE_BESTANDDELEN | CM7: KV_MEDIAAN_ZANDFRACTIE | CN7: KV_MEDIAAN_ALLEFRACTIES | CO7: KV_GRIND% | CP7: KV_ZAND% | CQ7: KV_SILT% | CR7: KV_DOOR_63MM | CS7: KV_DOOR_31.5MM | CT7: KV_DOOR_16MM | CU7: KV_DOOR_8MM | CV7: KV_DOOR_4MM | CW7: KV_DOOR_2MM | CX7: KV_DOOR_1MM | CY7: KV_DOOR_500MU | CZ7: KV_DOOR_250MU | DA7: KV_DOOR_180MU | DB7: KV_DOOR_125MU | DC7: KV_DOOR_63MU | DD7: KV_DOOR_32MU | DE7: KV_DOOR_20MU | DF7: KV_DOOR_16MU | DG7: KV_DOOR_2MU | DH7: KV_D70 | DI7: KV_D60 | DJ7: KV_D50 | DK7: KV_D10 | DL7: KV_CU_ZAND | DM7: CPT_FILENAAM_PDF | DN7: CPT_FILENAAM_GEF | DO7: CPT_NIVEAU | DP7: CPT_TRAJECTLENGTE_GEM | DQ7: CPT_CONUSWEERSTAND_GEM | DR7: CPT_WRIJVINGSWEERSTAND_GEM | DS7: CPT_WRIJVINGSGETAL_GEM | DT7: CPT_WATERSPANNING_GEM | DU7: CPT_QNET | DV7: CPT_QT | DW7: CPT_VO | DX7: CPT_KLASSE | DY7: CPT_A_FACTOR | DZ7: CPT_QBALL | EA7: CRS_FILENAAM_PDF | EB7: CRS_FILENAAM_SPANNINGSPAD | EC7: CRS_MONSTERID | ED7: CRS_LABORATORIUM | EE7: CRS_NORM | EF7: CRS_DATUM | EG7: CRS_GRONDSOORT | EH7: CRS_OVERIGE_BESTANDDELEN | EI7: CRS_MONSTERNIVEAU | EJ7: CRS_TERREINSPANNING | EK7: CRS_VOLUMEGEWICHT_NAT | EL7: CRS_VOLUMEGEWICHT_DRG | EM7: CRS_WATERGEHALTE_VOOR | EN7: CRS_WATERGEHALTE_NA_PROEF | EO7: CRS_VERZADIGING | EP7: CRS_TEMPERATUUR_PROEF_MAX | EQ7: CRS_TEMPERATUUR_PROEF_MIN | ER7: CRS_PROEFSTUKDIAMETER_VOOR | ES7: CRS_PROEFSTUKHOOGTE_VOOR | ET7: CRS_PROEFSTUKHOOGTE_NA_VERZADIGING | EU7: CRS_PROEFSTUKHOOGTE_NA_PROEF | EV7: CRS_REKSNELHEID_BELASTEN | EW7: CRS_REKSNELHEID_ONTLASTEN | EX7: CRS_RELAXATIEDUUR | EY7: CRS_EFF_SPANNING_START_RELAXATIE | EZ7: CRS_EFF_SPANNING_EIND_RELAXATIE | FA7: CRS_EFF_VERT_SPANNING_START_ONTLASTEN | FB7: CRS_EFF_VERT_SPANNING_EIND_ONTLASTEN | FC7: CRS_EFF_VERT_SPANNING_EIND_PROEF | FD7: CRS_MAX_REL_WATEROVERSPANNING_PROEF | FE7: CRS_GRENSSPANNING_A | FF7: CRS_REK_BIJ_GRENSSPANNING_A | FG7: CRS_BOVENGRENS_GRENSSPANNING_B | FH7: CRS_ISOTACHE_A | FI7: CRS_ISOTACHE_B | FJ7: CRS_ISOTACHE_C | FK7: SD_FILENAAM_PDF | FL7: SD_FILENAAM_SPANNINGSPAD | FM7: SD_MONSTERID | FN7: SD_LABORATORIUM | FO7: SD_NORM | FP7: SD_DATUM | FQ7: SD_GRONDSOORT | FR7: SD_OVERIGE_BESTANDDELEN | FS7: SD_MONSTERNIVEAU | FT7: SD_TERREINSPANNING | FU7: SD_VOLUMEGEWICHT_NAT | FV7: SD_VOLUMEGEWICHT_DR | FW7: SD_WATERGEHALTE_INI | FX7: SD_WATERGEHALTE_NA_PROEF | FY7: SD_PORIENGETAL | FZ7: SD_MAX_TEMPERATUUR_PROEF | GA7: SD_MIN_TEMPERATUUR_PROEF | GB7: SD_BELAST_ONTLASTSTAPPEN | GC7: SD_TYPEPROEF | GD7: SD_BJERRUM_GRENSSPANNING | GE7: SD_BJERRUM_REK_BIJ_GRENSSPANNING | GF7: SD_BJERRUM_CC | GG7: SD_BJERRUM_CC_TRAP1_2 | GH7: SD_BJERRUM_CC_TRAP2_3 | GI7: SD_BJERRUM_CC_TRAP3_4 | GJ7: SD_BJERRUM_CC_TRAP4_5 | GK7: SD_BJERRUM_CC_TRAP5_6 | GL7: SD_BJERRUM_CC_TRAP6_7 | GM7: SD_BJERRUM_CC_TRAP7_8 | GN7: SD_BJERRUM_CC_TRAP8_9 | GO7: SD_BJERRUM_CC_TRAP9_10 | GP7: SD_BJERRUM_CR | GQ7: SD_BJERRUM_CR_TRAP1_2 | GR7: SD_BJERRUM_CR_TRAP2_3 | GS7: SD_BJERRUM_CR_TRAP3_4 | GT7: SD_BJERRUM_CR_TRAP4_5 | GU7: SD_BJERRUM_CR_TRAP5_6 | GV7: SD_BJERRUM_CR_TRAP6_7 | GW7: SD_BJERRUM_CR_TRAP7_8 | GX7: SD_BJERRUM_SR_TRAP8_9 | GY7: SD_BJERRUM_RR_TRAP9_10 | GZ7: SD_BJERRUM_CALPHA | HA7: SD_BJERRUM_CALPHA_TRAP1 | HB7: SD_BJERRUM_CALPHA_TRAP2 | HC7: SD_BJERRUM_CALPHA_TRAP3 | HD7: SD_BJERRUM_CALPHA_TRAP4 | HE7: SD_BJERRUM_CALPHA_TRAP5 | HF7: SD_BJERRUM_CALPHA_TRAP6 | HG7: SD_BJERRUM_CALPHA_TRAP7 | HH7: SD_BJERRUM_CALPHA_TRAP8 | HI7: SD_BJERRUM_CALPHA_TRAP9 | HJ7: SD_BJERRUM_CALPHA_TRAP10 | HK7: SD_BJERRUM_V0 | HL7: SD_KOPPEJAN_GRENSSPANNING | HM7: SD_KOPPEJAN_REK_BIJ_GRENSSPANNING | HN7: SD_KOPPEJAN_C | HO7: SD_KOPPEJAN_C' | HP7: SD_KOPPEJAN_C_TRAP2_3 | HQ7: SD_KOPPEJAN_C_TRAP3_4 | HR7: SD_KOPPEJAN_C_TRAP4_5 | HS7: SD_KOPPEJAN_C_TRAP5_6 | HT7: SD_KOPPEJAN_C_TRAP6_7 | HU7: SD_KOPPEJAN_C_TRAP7_8 | HV7: SD_KOPPEJAN_C_TRAP8_9 | HW7: SD_KOPPEJAN_CP | HX7: SD_KOPPEJAN_C'P | HY7: SD_KOPPEJAN_CP_TRAP2_3 | HZ7: SD_KOPPEJAN_CP_TRAP3_4 | IA7: SD_KOPPEJAN_CP_TRAP4_5 | IB7: SD_KOPPEJAN_CP_TRAP5_6 | IC7: SD_KOPPEJAN_CP_TRAP6_7 | ID7: SD_KOPPEJAN_CP_TRAP7_8 | IE7: SD_KOPPEJAN_CP_TRAP8_9 | IF7: SD_KOPPEJAN_CS | IG7: SD_KOPPEJAN_C'S | IH7: SD_KOPPEJAN_CS_TRAP2_3 | II7: SD_KOPPEJAN_CS_TRAP3_4 | IJ7: SD_KOPPEJAN_CS_TRAP4_5 | IK7: SD_KOPPEJAN_CS_TRAP5_6 | IL7: SD_KOPPEJAN_CS_TRAP6_7 | IM7: SD_KOPPEJAN_CS_TRAP7_8 | IN7: SD_KOPPEJAN_CS_TRAP8_9 | IO7: SD_ISOTACHE_A | IP7: SD_ISOTACHE_B | IQ7: SD_ISOTACHE_C | IR7: SD_ISOTACHE_GRENSSPANNING_A | IS7: SD_ISOTACHE_REK_BIJ_GRENSSPANNING_A | IT7: SD_ISOTACHE_BOVENGRENS_GRENSSPANNING_B | IU7: SD_CASAGRANDE_CV10_TRAP2 | IV7: SD_CASAGRANDE_CV10_TRAP3 | IW7: SD_CASAGRANDE_CV10_TRAP4 | IX7: SD_CASAGRANDE_CV10_TRAP5 | IY7: SD_CASAGRANDE_CV10_TRAP6 | IZ7: SD_CASAGRANDE_CV10_TRAP7 | JA7: SD_CASAGRANDE_CV10_TRAP8 | JB7: SD_CASAGRANDE_CV10_TRAP9 | JC7: SD_CASAGRANDE_K10_TRAP2 | JD7: SD_CASAGRANDE_K10_TRAP3 | JE7: SD_CASAGRANDE_K10_TRAP4 | JF7: SD_CASAGRANDE_K10_TRAP5 | JG7: SD_CASAGRANDE_K10_TRAP6 | JH7: SD_CASAGRANDE_K10_TRAP7 | JI7: SD_CASAGRANDE_K10_TRAP8 | JJ7: SD_CASAGRANDE_K10_TRAP9 | JK7: SD_CASAGRANDE_MV_TRAP2 | JL7: SD_CASAGRANDE_MV_TRAP3 | JM7: SD_CASAGRANDE_MV_TRAP4 | JN7: SD_CASAGRANDE_MV_TRAP5 | JO7: SD_CASAGRANDE_MV_TRAP6 | JP7: SD_CASAGRANDE_MV_TRAP7 | JQ7: SD_CASAGRANDE_MV_TRAP8 | JR7: SD_CASAGRANDE_MV_TRAP9 | JS7: SD_CASAGRANDE_SPANNING_CV10_TRAP2 | JT7: SD_CASAGRANDE_SPANNING_CV10_TRAP3 | JU7: SD_CASAGRANDE_SPANNING_CV10_TRAP4 | JV7: SD_CASAGRANDE_SPANNING_CV10_TRAP5 | JW7: SD_CASAGRANDE_SPANNING_CV10_TRAP6 | JX7: SD_CASAGRANDE_SPANNING_CV10_TRAP7 | JY7: SD_CASAGRANDE_SPANNING_CV10_TRAP8 | JZ7: SD_CASAGRANDE_SPANNING_CV10_TRAP9 | KA7: SD_TAYLOR_CV10_TRAP2 | KB7: SD_TAYLOR_CV10_TRAP3 | KC7: SD_TAYLOR_CV10_TRAP4 | KD7: SD_TAYLOR_CV10_TRAP5 | KE7: SD_TAYLOR_CV10_TRAP6 | KF7: SD_TAYLOR_CV10_TRAP7 | KG7: SD_TAYLOR_CV10_TRAP8 | KH7: SD_TAYLOR_CV10_TRAP9 | KI7: SD_TAYLOR_K10_TRAP2 | KJ7: SD_TAYLOR_K10_TRAP3 | KK7: SD_TAYLOR_K10_TRAP4 | KL7: SD_TAYLOR_K10_TRAP5 | KM7: SD_TAYLOR_K10_TRAP6 | KN7: SD_TAYLOR_K10_TRAP7 | KO7: SD_TAYLOR_K10_TRAP8 | KP7: SD_TAYLOR_K10_TRAP9 | KQ7: SD_TAYLOR_MV_TRAP2 | KR7: SD_TAYLOR_MV_TRAP3 | KS7: SD_TAYLOR_MV_TRAP4 | KT7: SD_TAYLOR_MV_TRAP5 | KU7: SD_TAYLOR_MV_TRAP6 | KV7: SD_TAYLOR_MV_TRAP7 | KW7: SD_TAYLOR_MV_TRAP8 | KX7: SD_TAYLOR_MV_TRAP9 | KY7: SD_TAYLOR_SPANNING_CV10_TRAP2 | KZ7: SD_TAYLOR_SPANNING_CV10_TRAP3 | LA7: SD_TAYLOR_SPANNING_CV10_TRAP4 | LB7: SD_TAYLOR_SPANNING_CV10_TRAP5 | LC7: SD_TAYLOR_SPANNING_CV10_TRAP6 | LD7: SD_TAYLOR_SPANNING_CV10_TRAP7 | LE7: SD_TAYLOR_SPANNING_CV10_TRAP8 | LF7: SD_TAYLOR_SPANNING_CV10_TRAP9 | LG7: DSS_FILENAAM_PDF | LH7: DSS_FILENAAM_SPANNINGSPAD | LI7: DSS_MONSTERID | LJ7: DSS_LABORATORIUM | LK7: DSS_NORM | LL7: DSS_DATUM | LM7: DSS_GRONDSOORT | LN7: DSS_OVERIGE_BESTANDDELEN | LO7: DSS_MONSTERNIVEAU | LP7: DSS_TERREINSPANNING | LQ7: DSS_VOLUMEGEWICHT_NAT | LR7: DSS_VOLUMEGEWICHT_DRG | LS7: DSS_WATERGEHALTE_VOOR | LT7: DSS_WATERGEHALTE_NA_PROEF | LU7: DSS_VERZADIGINGGRAAD_VOOR | LV7: DSS_PORIENGETAL_VOOR | LW7: DSS_PORIENGETAL_EINDE_CONSOLIDATIE | LX7: DSS_SPECIFIEKE_MASSA | LY7: DSS_TEMPERATUUR_PROEF_MAX | LZ7: DSS_TEMPERATUUR_PROEF_MIN | MA7: DSS_PROEFSTUKDIAMETER_VOOR | MB7: DSS_PROEFSTUKHOOGTE_VOOR | MC7: DSS_PROEFSTUKHOOGTE_NA_CONSOLIDATIE | MD7: DSS_UITGEVOERDE_CORRECTIES | ME7: DSS_UITVOERINGSWIJZE | MF7: DSS_MAX_EFF_VERT_SPANNING_CONSOLIDATIE | MG7: DSS_EFF_VERT_SPANNING_EINDE_CONSOLIDATIE | MH7: DSS_OCR | MI7: DSS_AXIALEREK_EINDE_CONSOLIDATIE | MJ7: DSS_BELASTINGSSTAPPEN_CONSOLIDATIE | MK7: DSS_DUUR_CONSOLIDATIE | ML7: DSS_AFSCHUIFSNELHEID_%UUR | MM7: DSS_AFSCHUIFSNELHEID_MMUUR | MN7: DSS_S_2% | MO7: DSS_T_2% | MP7: DSS_S_5% | MQ7: DSS_T_5% | MR7: DSS_S_10% | MS7: DSS_T_10% | MT7: DSS_S_15% | MU7: DSS_T_15% | MV7: DSS_S_20% | MW7: DSS_T_20% | MX7: DSS_S_BIJ_T_MAX | MY7: DSS_T_MAX | MZ7: DSS_REK_BIJ_T_MAX | NA7: DSS_S_BIJ_T_EIND | NB7: DSS_T_EIND | NC7: DSS_REK_BIJ_T_EIND | ND7: DSS_S_BIJ_MAX_S1S3 | NE7: DSS_T_BIJ_MAX_S1S3 | NF7: DSS_REK_BIJ_MAX_S1S3 | NG7: DSS_SCHUIFMODULUS_G50 | NH7: TXT_SS_FILENAAM_PDF | NI7: TXT_SS_FILENAAM_SPANNINGSPAD | NJ7: TXT_SS_MONSTERID | NK7: TXT_SS_LABORATORIUM | NL7: TXT_SS_NORM | NM7: TXT_SS_DATUM | NN7: TXT_SS_GRONDSOORT | NO7: TXT_SS_OVERIGE_BESTANDDELEN | NP7: TXT_SS_MONSTERNIVEAU | NQ7: TXT_SS_TERREINSPANNING | NR7: TXT_SS_VOLUMEGEWICHT_NAT | NS7: TXT_SS_VOLUMEGEWICHT_DRG | NT7: TXT_SS_WATERGEHALTE_NA_PROEF | NU7: TXT_SS_WATERGEHALTE_VOOR | NV7: TXT_SS_VERZADIGINGSGRAAD_VOOR | NW7: TXT_SS_PORIENGETAL_VOOR | NX7: TXT_SS_SPECIFIEKE_MASSA | NY7: TXT_SS_TEMPERATUUR_PROEF_MAX | NZ7: TXT_SS_TEMPERATUUR_PROEF_MIN | OA7: TXT_SS_PROEFSTUKDIAMETER_VOOR | OB7: TXT_SS_PROEFSTUKHOOGTE_VOOR | OC7: TXT_SS_TYPE_PROEF | OD7: TXT_SS_MEMBRAANCORRECTIE | OE7: TXT_SS_OVERIGECORRECTIES | OF7: TXT_SS_BACKPRESSURE | OG7: TXT_SS_CONSOLIDATIEWIJZE | OH7: TXT_SS_SPANNINGSVERHOUDING_STOPCR_K | OI7: TXT_SS_STOPCRITERIUM_CONSOLIDATIE | OJ7: TXT_SS_S'_ISOTROOP_CONSOLIDATIE | OK7: TXT_SS_T_ISOTROOP_CONSOLIDATIE | OL7: TXT_SS_S'_MAX_CONSOLIDATIE | OM7: TXT_SS_T_MAX_CONSOLIDATIE | ON7: TXT_SS_S'_EIND_CONSOLIDATIE | OO7: TXT_SS_T_EIND_CONSOLIDATIE | OP7: TXT_SS_OCR | OQ7: TXT_SS_AXIALEREK_CONSOLIDATIE | OR7: TXT_SS_VOLUMEREK_CONSOLIDATIE | OS7: TXT_SS_STOPCRITERIUM_AFSCHUIVEN | OT7: TXT_SS_AXIALEREKSNELHEID_AFSCHUIVEN | OU7: TXT_SS_S'_2% | OV7: TXT_SS_T_2% | OW7: TXT_SS_S'_5% | OX7: TXT_SS_T_5% | OY7: TXT_SS_S'_15% | OZ7: TXT_SS_T_15% | PA7: TXT_SS_S'_BIJ_T_PIEK | PB7: TXT_SS_T_PIEK | PC7: TXT_SS_REK_BIJ_T_PIEK | PD7: TXT_SS_S'_BIJ_T_EIND | PE7: TXT_SS_T_EIND | PF7: TXT_SS_REK_BIJ_T_EIND | PG7: TXT_SS_E_UNDR50 | PH7: TXT_SS_REK_BIJ_E_UNDR50 | PI7: TXT_SS_SKEMPTON_A | PJ7: TXT_MS_FILENAAM_PDF | PK7: TXT_MS_FILENAAM_SPANNINGSPAD | PL7: TXT_MS_MONSTERID | PM7: TXT_MS_LABORATORIUM | PN7: TXT_MS_CONSOLIDATIESPANNING | PO7: TXT_MS_REK_BIJ_E_UNDR50 | PP7: TXT_MS_E_UNDR50 | PQ7: TXT_MS_S1'_2% | PR7: TXT_MS_S2'_2% | PS7: TXT_MS_S3'_2% | PT7: TXT_MS_T1_2% | PU7: TXT_MS_T2_2% | PV7: TXT_MS_T3_2% | PW7: TXT_MS_C_2% | PX7: TXT_MS_PHI_2% | PY7: TXT_MS_S1'_5% | PZ7: TXT_MS_S2'_5% | QA7: TXT_MS_S3'_5% | QB7: TXT_MS_T1_5% | QC7: TXT_MS_T2_5% | QD7: TXT_MS_T3_5% | QE7: TXT_MS_C_5% | QF7: TXT_MS_PHI_5% | QG7: CEL_FILENAAM_PDF | QH7: CEL_FILENAAM_SPANNINGSPAD | QI7: CEL_PHI1 | QJ7: CEL_C1 | QK7: CEL_PHI2 | QL7: CEL_C2 | QM7: CEL_PHI3 | QN7: CEL_C3 | QO7: CEL_PHI4 | QP7: CEL_C4 | QQ7: CEL_PHI5 | QR7: CEL_C5 | QS7: CEL_EINDSPANNING | QT7: PV_NAAM | QU7: PV_OPMERKING | QV7: ANA_TERREINSPANNING | QW7: ANA_TXT_MAX_VERTICALE_CONSOLIDATIE_SPANNING | QX7: ANA_DSS_MAX_CONSOLIDATIE_SPANNING | QY7: ANA_TXT_CONSOLIDATIE_TYPE_VOORSTEL | QZ7: ANA_TXT_CONSOLIDATIE_TYPE_HANDMATIG | RA7: ANA_TXT_CONSOLIDATIE_TYPE_REKEN | RB7: ANA_DSS_CONSOLIDATIE_TYPE_VOORSTEL | RC7: ANA_DSS_CONSOLIDATIE_TYPE_HANDMATIG | RD7: ANA_DSS_CONSOLIDATIE_TYPE_REKEN | RE7: ANA_GRENSSPANNING_PROEF | RF7: ANA_POP_VELD | RG7: ANA_POP_VELD_GEMIDDELD | RH7: ANA_GRENSSPANNING_VOORSTEL | RI7: ANA_GRENSSPANNING_HANDMATIG | RJ7: ANA_GRENSSPANNING_REKEN | RK7: OCR_TXT | RL7: OCR_DSS
A8: =Table1[[#This Row],[ALG__REGEL]]&"_"&Table1[[#This Row],[BORING_NUMMER]]&"_"&Table1[[#This Row],[MONSTER_ID]] -> 1_B01-K01_8-K405 | B8: 1 | C8: FALSE | G8: TRUE | H8: FALSE | I8: TRUE | J8: FALSE | K8: Waterschap | L8: Voorbeeld | N8: Polderdijk | O8: B01-K | Q8: Regionaal | V8: 78935.54 | W8: 446497.69 | X8: 0.055 | Y8: B01-K01 | Z8: KR | AA8: 45754 | AB8: Voorbeeld.pdf | AD8: Voorbeeld | AF8: Pulsboor | AG8: -1.995 | AI8: 8-K405 | AK8: Koelruimte 10°C en 85% luchtvochtigheid | AL8: -3.545 | AM8: -3.945 | AN8: 3.6 | AO8: 4 | AT8: Voorbeeld | AW8: Veen, kleiïg, bruin, donker, Pulsinstallatie machinaal | AX8: kleiïg | EA8: OED_CRS30)GA250495_B01-K01_8-K405.pdf | EC8: B01-K01_8-K405 | ED8: Voorbeeld | EE8: ASTM 4168 M | EF8: 45917 | EG8: Veen, kleiïg, bruin, donker, Pulsinstallatie machinaal | EH8: kleiïg | EI8: -3.87 | EJ8: 49.2 | EK8: 9.9 | EL8: 1.7 | EM8: 490.4 | EN8: 301.9 | ER8: 63.5 | ES8: 22 | ET8: 21.95 | EU8: 11.93 | EV8: 0.5 | EW8: -0.5 | EX8: 16 | EY8: 176.1 | EZ8: 129.1 | FA8: 117.5 | FB8: 29.9 | FC8: 292.7 | FD8: 0.1 | FE8: 57.3 | FF8: 13.15 | FG8: 105 | FH8: 0.0389 | FI8: 0.295 | FJ8: 0.0194 | LG8: DSS7)GA250495_B01-K01_8-K405.pdf | LH8: DSS7)GA250495_B01-K01_8-K405_ASCII.txt | LI8: 8-K405 | LJ8: Voorbeeld | LK8: ASTM D6528 | LL8: 45883 | LM8: Veen, kleiïg, bruin, donker, Pulsinstallatie machinaal | LN8: kleiïg | LO8: -3.75 | LP8: 49.3 | LQ8: 9.6449541 | LR8: 1.6322582 | LS8: 490.89636 | LT8: 494.39252 | LV8: 12.380839 | LW8: 10.627698 | LX8: 2226.4 | LY8: 20 | LZ8: 20 | MA8: 63 | MB8: 25 | MC8: 21.7 | MD8: Conform 1207808-007-GEO-0002-v3-r-Dijken op Veen II en 1230090-019-GEO-0002-v03-r-Protocol laboratoriumproeven voor grondonderzoek aan waterkeringen | ME8: Constante hoogte | MF8: 50.3 | MG8: 50.3 | MI8: 13.09955 | MJ8: 1 | MK8: 20.048379 | ML8: 5 | MM8: 1.0862265 | MN8: 46.877508 | MO8: 7.0255506 | MP8: 43.448697 | MQ8: 12.029342 | MR8: 41.944437 | MS8: 16.009889 | MT8: 41.284872 | MU8: 18.065117 | MV8: 41.151829 | MW8: 19.16591 | MX8: 41.168395 | MY8: 19.779527 | MZ8: 27.998826 | NA8: 40.241155 | NB8: 19.432292 | NC8: 40 | NG8: 289.86352 | QT8: DSS_voorbeeld | QV8: 49.3 | QX8: 50.3 | RB8: OC | RD8: OC | RE8: 57.3 | RF8: 8 | RG8: 10.15 | RJ8: 57.3 | RL8: 1.1622718
A9: =Table1[[#This Row],[ALG__REGEL]]&"_"&Table1[[#This Row],[BORING_NUMMER]]&"_"&Table1[[#This Row],[MONSTER_ID]] -> 2_B01-K02_8-505 | B9: 2 | C9: FALSE | G9: FALSE | H9: FALSE | I9: TRUE | J9: FALSE | K9: Waterschap | L9: Voorbeeld | N9: Polderdijk | O9: B01-K | Q9: Regionaal | V9: 78940.35 | W9: 446498.06 | X9: 0.044 | Y9: B01-K02 | Z9: KR | AA9: 45754 | AB9: Voorbeeld.pdf | AD9: Voorbeeld | AF9: Pulsboor | AG9: -1.996 | AI9: 8-505 | AK9: Koelruimte 10°C en 85% luchtvochtigheid | AL9: -3.556 | AM9: -3.956 | AN9: 3.6 | AO9: 4 | AT9: Voorbeeld | AW9: Veen, kleiïg, bruin, donker, Pulsinstallatie machinaal, Laag | AX9: kleiïg | LG9: DSS9)GA250495_B01-K02_8-505.pdf | LH9: DSS9)GA250495_B01-K02_8-505_ASCII.txt | LI9: 8-505 | LJ9: Voorbeeld | LK9: ASTM D6528 | LL9: 45887 | LM9: Veen, kleiïg, bruin, donker, Pulsinstallatie machinaal, Laag | LN9: kleiïg | LO9: -3.85 | LP9: 46.3 | LQ9: 9.3944522 | LR9: 1.4242997 | LS9: 559.58395 | LT9: 530 | LV9: 9.1612695 | LW9: 7.9062003 | LX9: 1475.3 | LY9: 20 | LZ9: 20 | MA9: 63 | MB9: 25 | MC9: 21.9 | MD9: Conform 1207808-007-GEO-0002-v3-r-Dijken op Veen II en 1230090-019-GEO-0002-v03-r-Protocol laboratoriumproeven voor grondonderzoek aan waterkeringen | ME9: Constante hoogte | MF9: 46.3 | MG9: 46.3 | MI9: 12.349358 | MJ9: 1 | MK9: 20.045586 | ML9: 5 | MM9: 1.0956062 | MN9: 42.822251 | MO9: 7.211976 | MP9: 40.919683 | MQ9: 12.544427 | MR9: 39.768661 | MS9: 16.908245 | MT9: 38.939729 | MU9: 19.261539 | MV9: 38.344812 | MW9: 20.392407 | MX9: 35.623089 | MY9: 20.891441 | MZ9: 30.992232 | NA9: 33.452208 | NB9: 20.634183 | NC9: 40 | NG9: 294.35723 | QT9: DSS_voorbeeld | QV9: 46.3 | QX9: 46.3 | RB9: OC | RD9: OC | RI9: 70 | RJ9: 70 | RL9: 1.511879
A10: =Table1[[#This Row],[ALG__REGEL]]&"_"&Table1[[#This Row],[BORING_NUMMER]]&"_"&Table1[[#This Row],[MONSTER_ID]] -> 3_B02-AL01_14-1088 | B10: 3 | C10: FALSE | G10: TRUE | H10: FALSE | I10: TRUE | J10: FALSE | K10: Waterschap | L10: Voorbeeld | N10: Polderdijk | O10: B02-AL | Q10: Regionaal | V10: 87074.07 | W10: 441147.4 | X10: -1.768 | Y10: B02-AL01 | Z10: AL | AA10: 45754 | AB10: Voorbeeld.pdf | AD10: Voorbeeld | AF10: Pulsboor | AG10: -3.298 | AI10: 14-1088 | AK10: Koelruimte 10°C en 85% luchtvochtigheid | AL10: -7.768 | AM10: -8.168 | AN10: 6 | AO10: 6.4 | AT10: Voorbeeld | AW10: Veen, kleiïg, bruin, donker, Pulsinstallatie machinaal, Geen sterkte | AX10: kleiïg | EA10: OED_CRS9)GA250495_B02-AL01_14-1088.pdf | EC10: B02-AL01_14-1088 | ED10: Voorbeeld | EE10: ASTM 4168 M | EF10: 45874 | EG10: Veen, kleiïg, bruin, donker, Pulsinstallatie machinaal, Geen sterkte | EH10: kleiïg | EI10: -8.04 | EJ10: 49.3 | EK10: 10.1 | EL10: 1.7 | EM10: 486.5 | EN10: 334.1 | ER10: 63.5 | ES10: 22 | ET10: 21.95 | EU10: 12.84 | EV10: 0.5 | EW10: -0.5 | EX10: 16 | EY10: 172.9 | EZ10: 140.6 | FA10: 115.6 | FB10: 30.4 | FC10: 292.6 | FD10: 0.5 | FE10: 67.9 | FF10: 6.53 | FG10: 125 | FH10: 0.0507 | FI10: 0.323 | FJ10: 0.0139 | LG10: DSS3)GA250495_B02-AL01_14-1088.pdf | LH10: DSS3)GA250495_B02-AL01_14-1088_ASCII.txt | LI10: 14-1088 | LJ10: Voorbeeld | LK10: ASTM D6528 | LL10: 45876 | LM10: Veen, kleiïg, bruin, donker, Pulsinstallatie machinaal, Geen sterkte | LN10: kleiïg | LO10: -9.79 | LP10: 49.3 | LQ10: 9.9747607 | LR10: 1.7704541 | LS10: 463.40125 | LT10: 494.89872 | LV10: 7.113615 | LW10: 6.4182765 | LX10: 1464.3 | LY10: 20 | LZ10: 20 | MA10: 63 | MB10: 25 | MC10: 22.86 | MD10: Conform 1207808-007-GEO-0002-v3-r-Dijken op Veen II en 1230090-019-GEO-0002-v03-r-Protocol laboratoriumproeven voor grondonderzoek aan waterkeringen | ME10: Constante hoogte | MF10: 49.3 | MG10: 49.3 | MI10: 8.5660539 | MJ10: 1 | MK10: 20.043012 | ML10: 5 | MM10: 1.1428748 | MN10: 44.236297 | MO10: 10.595282 | MP10: 42.213659 | MQ10: 18.627326 | MR10: 40.074137 | MS10: 24.699932 | MT10: 39.35481 | MU10: 26.821697 | MV10: 40.142424 | MW10: 27.184765 | MX10: 39.955955 | MY10: 27.224398 | MZ10: 18.98719 | NA10: 44.668245 | NB10: 26.498493 | NC10: 40 | NG10: 469.46461 | QT10: DSS_voorbeeld | QV10: 49.3 | QX10: 49.3 | RB10: OC | RD10: OC | RE10: 67.9 | RF10: 18.6 | RG10: 20.066667 | RJ10: 67.9 | RL10: 1.3772819
A11: =Table1[[#This Row],[ALG__REGEL]]&"_"&Table1[[#This Row],[BORING_NUMMER]]&"_"&Table1[[#This Row],[MONSTER_ID]] -> 4_B02-AL01_15-1321 | B11: 4 | C11: FALSE | G11: FALSE | H11: FALSE | I11: TRUE | J11: FALSE | K11: Waterschap | L11: Voorbeeld | N11: Polderdijk | O11: B02-AL | Q11: Regionaal | V11: 87074.07 | W11: 441147.4 | X11: -1.768 | Y11: B02-AL01 | Z11: AL | AA11: 45754 | AB11: Voorbeeld.pdf | AD11: Voorbeeld | AF11: Pulsboor | AG11: -3.298 | AI11: 15-1321 | AK11: Koelruimte 10°C en 85% luchtvochtigheid | AL11: -8.168 | AM11: -8.568 | AN11: 6.4 | AO11: 6.8 | AT11: Voorbeeld | AW11: Veen, kleiïg, bruin, donker, Pulsinstallatie machinaal, Geen sterkte | AX11: kleiïg | LG11: DSS4)GA250495_B02-AL01_15-1321.pdf | LH11: DSS4)GA250495_B02-AL01_15-1321_ASCII.txt | LI11: 15-1321 | LJ11: Voorbeeld | LK11: ASTM D6528 | LL11: 45877 | LM11: Veen, kleiïg, bruin, donker, Pulsinstallatie machinaal, Geen sterkte | LN11: kleiïg | LO11: -10.17 | LP11: 49.3 | LQ11: 10.052807 | LR11: 1.9202718 | LS11: 423.50956 | LT11: 457.23997 | LV11: 6.5679567 | LW11: 6.1799963 | LX11: 1481.4 | LY11: 20 | LZ11: 20 | MA11: 63 | MB11: 25 | MC11: 23.63 | MD11: Conform 1207808-007-GEO-0002-v3-r-Dijken op Veen II en 1230090-019-GEO-0002-v03-r-Protocol laboratoriumproeven voor grondonderzoek aan waterkeringen | ME11: Constante hoogte | MF11: 49.3 | MG11: 49.3 | MI11: 5.1240728 | MJ11: 1 | MK11: 20.034977 | ML11: 5 | MM11: 1.1859206 | MN11: 46.348482 | MO11: 12.500709 | MP11: 44.10357 | MQ11: 22.579929 | MR11: 40.987905 | MS11: 29.690244 | MT11: 38.614433 | MU11: 30.95396 | MV11: 36.422961 | MW11: 30.986551 | MX11: 37.259092 | MY11: 31.103657 | MZ11: 18.169145 | NA11: 29.129659 | NB11: 28.061556 | NC11: 40 | NG11: 572.88001 | QT11: DSS_voorbeeld | QV11: 49.3 | QX11: 49.3 | RB11: OC | RD11: OC | RG11: 20.066667 | RH11: 69.366667 | RJ11: 69.366667 | RL11: 1.4070318
A12: =Table1[[#This Row],[ALG__REGEL]]&"_"&Table1[[#This Row],[BORING_NUMMER]]&"_"&Table1[[#This Row],[MONSTER_ID]] -> 5_B02-K01_16-667 | B12: 5 | C12: FALSE | G12: TRUE | H12: FALSE | I12: TRUE | J12: FALSE | K12: Waterschap | L12: Voorbeeld | N12: Polderdijk | O12: B02-K | Q12: Regionaal | V12: 87081.94 | W12: 441144.12 | X12: -0.167 | Y12: B02-K01 | Z12: KR | AA12: 45754 | AB12: Voorbeeld.pdf | AD12: Voorbeeld | AF12: Pulsboor | AG12: -3.147 | AI12: 16-667 | AK12: Koelruimte 10°C en 85% luchtvochtigheid | AL12: -6.967 | AM12: -7.367 | AN12: 6.8 | AO12: 7.2 | AT12: Voorbeeld | AW12: Veen, bruin, donker, Pulsinstallatie machinaal, Laag | EA12: OED_CRS15)GA250495_B02-K01_16-667.pdf | EC12: B02-K01_16-667 | ED12: Voorbeeld | EE12: ASTM 4168 M | EF12: 45880 | EG12: Veen, bruin, donker, Pulsinstallatie machinaal, Laag | EI12: -7.29 | EJ12: 60.7 | EK12: 9.8 | EL12: 1.6 | EM12: 522 | EN12: 316.3 | ER12: 63.5 | ES12: 22 | ET12: 21.95 | EU12: 11.62 | EV12: 0.5 | EW12: -0.5 | EX12: 16 | EY12: 372.5 | EZ12: 278.2 | FA12: 247.4 | FB12: 65.1 | FC12: 621.6 | FD12: 0.3 | FE12: 67.8 | FF12: 9.68 | FG12: 90 | FH12: 0.029 | FI12: 0.247 | FJ12: 0.0164 | LG12: DSS5)GA250495_B02-K01_16-667.pdf | LH12: DSS5)GA250495_B02-K01_16-667_ASCII.txt | LI12: 16-667 | LJ12: Voorbeeld | LK12: ASTM D6528 | LL12: 45881 | LM12: Veen, bruin, donker, Pulsinstallatie machinaal, Laag | LO12: -7.12 | LP12: 60.7 | LQ12: 10.035183 | LR12: 1.6749329 | LS12: 499.13941 | LT12: 485.09834 | LV12: 7.6313887 | LW12: 6.6771617 | LX12: 1473.7 | LY12: 20 | LZ12: 20 | MA12: 63 | MB12: 25 | MC12: 22.22 | MD12: Conform 1207808-007-GEO-0002-v3-r-Dijken op Veen II en 1230090-019-GEO-0002-v03-r-Protocol laboratoriumproeven voor grondonderzoek aan waterkeringen | ME12: Constante hoogte | MF12: 60.7 | MG12: 60.7 | MI12: 11.052488 | MJ12: 1 | MK12: 20.054582 | ML12: 5 | MM12: 1.1118086 | MN12: 56.835746 | MO12: 8.8377707 | MP12: 53.911947 | MQ12: 15.986324 | MR12: 50.225382 | MS12: 22.232453 | MT12: 47.77594 | MU12: 25.161584 | MV12: 46.151514 | MW12: 26.048086 | MX12: 46.093797 | MY12: 26.066964 | MZ12: 20.823459 | NA12: 39.711172 | NB12: 25.076201 | NC12: 40 | NG12: 364.93453 | QT12: DSS_voorbeeld | QV12: 60.7 | QX12: 60.7 | RB12: OC | RD12: OC | RE12: 67.8 | RF12: 7.1 | RG12: 7.1 | RJ12: 67.8 | RL12: 1.1169687
A13: =Table1[[#This Row],[ALG__REGEL]]&"_"&Table1[[#This Row],[BORING_NUMMER]]&"_"&Table1[[#This Row],[MONSTER_ID]] -> 6_B02-K02_17-22905 | B13: 6 | C13: FALSE | G13: TRUE | H13: FALSE | I13: TRUE | J13: FALSE | K13: Waterschap | L13: Voorbeeld | N13: Polderdijk | O13: B02-K | Q13: Regionaal | V13: 87083.63 | W13: 441148.12 | X13: -0.205 | Y13: B02-K02 | Z13: KR | AA13: 45754 | AB13: Voorbeeld.pdf | AD13: Voorbeeld | AF13: Pulsboor | AG13: -3.155 | AI13: 17-22905 | AK13: Koelruimte 10°C en 85% luchtvochtigheid | AL13: -7.405 | AM13: -7.805 | AN13: 7.2 | AO13: 7.6 | AT13: Voorbeeld | AW13: Veen, bruin, donker, Pulsinstallatie machinaal, Matig | EA13: OED_CRS18)GA250495_B02-K02_17-22905.pdf | EC13: B02-K02_17-22905 | ED13: Voorbeeld | EE13: ASTM 4168 M | EF13: 45895 | EG13: Veen, bruin, donker, Pulsinstallatie machinaal, Matig | EI13: -7.55 | EJ13: 55.8 | EK13: 9.1 | EL13: 1.6 | EM13: 474.4 | EN13: 312.6 | ER13: 63.5 | ES13: 22 | ET13: 21.96 | EU13: 11.5 | EV13: 0.5 | EW13: -0.5 | EX13: 16 | EY13: 189.7 | EZ13: 134.2 | FA13: 131.7 | FB13: 34.1 | FC13: 257.9 | FD13: 0.2 | FE13: 62.2 | FF13: 28.76 | FG13: 90 | FH13: 0.0469 | FI13: 0.32 | FJ13: 0.0241 | LG13: DSS8)GA250495_B02-K02_17-22905.pdf | LH13: DSS8)GA250495_B02-K02_17-22905_ASCII.txt | LI13: 17-22905 | LJ13: Voorbeeld | LK13: ASTM D6528 | LL13: 45883 | LM13: Veen, bruin, donker, Pulsinstallatie machinaal, Matig | LO13: -7.6 | LP13: 55.7 | LQ13: 9.5870491 | LR13: 1.5239805 | LS13: 529.0795 | LT13: 467.29282 | LV13: 8.5423423 | LW13: 6.2038016 | LX13: 1482.4 | LY13: 20 | LZ13: 20 | MA13: 63 | MB13: 25 | MC13: 18.85 | MD13: Conform 1207808-007-GEO-0002-v3-r-Dijken op Veen II en 1230090-019-GEO-0002-v03-r-Protocol laboratoriumproeven voor grondonderzoek aan waterkeringen | ME13: Constante hoogte | MF13: 56.7 | MG13: 56.7 | MI13: 24.502412 | MJ13: 1 | MK13: 20.060495 | ML13: 5 | MM13: 0.94366265 | MN13: 52.487227 | MO13: 10.769306 | MP13: 49.843347 | MQ13: 16.748992 | MR13: 47.007347 | MS13: 21.340435 | MT13: 46.214118 | MU13: 23.600171 | MV13: 44.961735 | MW13: 24.636906 | MX13: 40.926885 | MY13: 25.712796 | MZ13: 35.937253 | NA13: 40.747475 | NB13: 25.671808 | NC13: 40 | NG13: 461.21311 | QT13: DSS_voorbeeld | QV13: 55.8 | QX13: 56.7 | RB13: OC | RD13: OC | RE13: 62.2 | RF13: 6.4 | RG13: 8.9 | RJ13: 62.2 | RL13: 1.1146953
A14: =Table1[[#This Row],[ALG__REGEL]]&"_"&Table1[[#This Row],[BORING_NUMMER]]&"_"&Table1[[#This Row],[MONSTER_ID]] -> 7_B03-K01_2-K44 | B14: 7 | C14: FALSE | G14: TRUE | H14: FALSE | I14: TRUE | J14: FALSE | K14: Waterschap | L14: Voorbeeld | N14: Polderdijk | O14: B03-K | Q14: Regionaal | V14: 87513.65 | W14: 449526.42 | X14: -1.868 | Y14: B03-K01 | Z14: KR | AA14: 45754 | AB14: Voorbeeld.pdf | AD14: Voorbeeld | AF14: Pulsboor | AG14: -2.498 | AI14: 2-K44 | AK14: Koelruimte 10°C en 85% luchtvochtigheid | AL14: -3.068 | AM14: -3.468 | AN14: 1.2 | AO14: 1.6 | AT14: Voorbeeld | AW14: Veen, bruin, donker, Machinale Boring, Laag | EA14: OED_CRS50)GA250495_B03-K01_2-K 44.pdf | EC14: B03-K01_2-K 44 | ED14: Voorbeeld | EE14: ASTM 4168 M | EF14: 45936 | EG14: Veen, bruin, donker, Machinale Boring, Laag | EI14: -3.39 | EJ14: 12.3 | EK14: 9.7 | EL14: 1.7 | EM14: 479.7 | EN14: 389 | ER14: 63.5 | ES14: 25 | ET14: 25 | EU14: 18.54 | EV14: 0.5 | EW14: -0.5 | EX14: 16 | EY14: 42.1 | EZ14: 32.7 | FA14: 28.1 | FB14: 6.1 | FC14: 72.1 | FD14: 0.7 | FE14: 19.3 | FF14: 7.73 | FG14: 50 | FH14: 0.0242 | FI14: 0.168 | FJ14: 0.0091 | LG14: DSS15)GA250495_B03-K01_2-K44.pdf | LH14: DSS15)GA250495_B03-K01_2-K44_ASCII.txt | LI14: 2-K44 | LJ14: Voorbeeld | LK14: ASTM D6528 | LL14: 45925 | LM14: Veen, bruin, donker, Machinale Boring, Laag | LO14: -3.36 | LP14: 12.3 | LQ14: 9.5417322 | LR14: 1.2220113 | LS14: 680.82192 | LT14: 641.80851 | LV14: 11.748868 | LW14: 10.920548 | LX14: 1588.1 | LY14: 20 | LZ14: 20 | MA14: 63 | MB14: 25 | MC14: 23.36 | MD14: Conform 1207808-007-GEO-0002-v3-r-Dijken op Veen II en 1230090-019-GEO-0002-v03-r-Protocol laboratoriumproeven voor grondonderzoek aan waterkeringen | ME14: Constante hoogte | MF14: 12.3 | MG14: 12.3 | MI14: 6.4966724 | MJ14: 1 | MK14: 20.018632 | ML14: 5 | MM14: 1.168785 | MN14: 10.436513 | MO14: 3.5108151 | MP14: 9.8787772 | MQ14: 6.1523798 | MR14: 9.2559345 | MS14: 8.3091108 | MT14: 9.1185652 | MU14: 9.3801711 | MV14: 9.0521839 | MW14: 9.9584307 | MX14: 9.2295784 | MY14: 10.364935 | MZ14: 33.839442 | NA14: 9.4412967 | NB14: 10.213639 | NC14: 40 | NG14: 141.07234 | QT14: DSS_voorbeeld | QV14: 12.3 | QX14: 12.3 | RB14: OC | RD14: OC | RE14: 19.3 | RF14: 7 | RG14: 9.75 | RJ14: 19.3 | RL14: 1.5691057
A15: =Table1[[#This Row],[ALG__REGEL]]&"_"&Table1[[#This Row],[BORING_NUMMER]]&"_"&Table1[[#This Row],[MONSTER_ID]] -> 8_B03-K01_3-197 | B15: 8 | C15: FALSE | G15: FALSE | H15: FALSE | I15: TRUE | J15: FALSE | K15: Waterschap | L15: Voorbeeld | N15: Polderdijk | O15: B03-K | Q15: Regionaal | V15: 87513.65 | W15: 449526.42 | X15: -1.868 | Y15: B03-K01 | Z15: KR | AA15: 45754 | AB15: Voorbeeld.pdf | AD15: Voorbeeld | AF15: Pulsboor | AG15: -2.498 | AI15: 3-197 | AK15: Koelruimte 10°C en 85% luchtvochtigheid | AL15: -3.468 | AM15: -3.868 | AN15: 1.6 | AO15: 2 | AT15: Voorbeeld | AW15: Veen, plantenresten, weinig, bruin, donker, Pulsinstallatie machinaal, Laag | AX15: weinig plantenresten | LG15: DSS16)GA250495_B03-K01_3-197.pdf | LH15: DSS16)GA250495_B03-K01_3-197_ASCII.txt | LI15: 3-197 | LJ15: Voorbeeld | LK15: ASTM D6528 | LL15: 45925 | LM15: Veen, plantenresten, weinig, bruin, donker, Pulsinstallatie machinaal, Laag | LN15: weinig plantenresten | LO15: -3.76 | LP15: 12.7 | LQ15: 9.6487305 | LR15: 2.0390625 | LS15: 373.19444 | LT15: 357.55886 | LV15: 6.0842482 | LW15: 5.4831855 | LX15: 1472.5 | LY15: 20 | LZ15: 20 | MA15: 63 | MB15: 25 | MC15: 22.86 | MD15: Conform 1207808-007-GEO-0002-v3-r-Dijken op Veen II en 1230090-019-GEO-0002-v03-r-Protocol laboratoriumproeven voor grondonderzoek aan waterkeringen | ME15: Constante hoogte | MF15: 12.7 | MG15: 12.7 | MI15: 8.4835358 | MJ15: 1 | MK15: 20.01914 | ML15: 5 | MM15: 1.1439438 | MN15: 10.668925 | MO15: 3.9327234 | MP15: 10.36493 | MQ15: 5.8255637 | MR15: 10.419069 | MS15: 7.351225 | MT15: 10.95568 | MU15: 8.299986 | MV15: 11.874929 | MW15: 9.1095565 | MX15: 17.881788 | MY15: 11.145861 | MZ15: 44.956565 | NA15: 16.876196 | NB15: 10.792155 | NC15: 40 | NG15: 126.5148 | QT15: DSS_voorbeeld | QV15: 12.7 | QX15: 12.7 | RB15: OC | RD15: OC | RG15: 9.75 | RH15: 22.45 | RJ15: 22.45 | RL15: 1.7677165
A16: =Table1[[#This Row],[ALG__REGEL]]&"_"&Table1[[#This Row],[BORING_NUMMER]]&"_"&Table1[[#This Row],[MONSTER_ID]] -> 9_B03-K01_4-954 | B16: 9 | C16: FALSE | G16: TRUE | H16: FALSE | I16: TRUE | J16: FALSE | K16: Waterschap | L16: Voorbeeld | N16: Polderdijk | O16: B03-K | Q16: Regionaal | V16: 87513.65 | W16: 449526.42 | X16: -1.868 | Y16: B03-K01 | Z16: KR | AA16: 45754 | AB16: Voorbeeld.pdf | AD16: Voorbeeld | AF16: Pulsboor | AG16: -2.498 | AI16: 4-954 | AK16: Koelruimte 10°C en 85% luchtvochtigheid | AL16: -3.868 | AM16: -4.268 | AN16: 2 | AO16: 2.4 | AT16: Voorbeeld | AW16: Veen, plantenresten, weinig, bruin, donker, Pulsinstallatie machinaal, Laag | AX16: weinig plantenresten | EA16: OED_CRS51)GA250495_B03-K01_4-954.pdf | EC16: B03-K01_4-954 | ED16: Voorbeeld | EE16: ASTM 4168 M | EF16: 45936 | EG16: Veen, plantenresten, weinig, bruin, donker, Pulsinstallatie machinaal, Laag | EH16: weinig plantenresten | EI16: -4.19 | EJ16: 13 | EK16: 9.8 | EL16: 1.2 | EM16: 713.5 | EN16: 557.7 | ER16: 63.5 | ES16: 25 | ET16: 25 | EU16: 17.17 | EV16: 0.5 | EW16: -0.5 | EX16: 16 | EY16: 49.4 | EZ16: 40 | FA16: 33.2 | FB16: 11.3 | FC16: 80.5 | FD16: -0.1 | FE16: 25.5 | FF16: 2.63 | FG16: 45 | FH16: 0.0402 | FI16: 0.304 | FJ16: 0.014 | LG16: DSS17)GA250495_B03-K01_4-954.pdf | LH16: DSS17)GA250495_B03-K01_4-954_ASCII.txt | LI16: 4-954 | LJ16: Voorbeeld | LK16: ASTM D6528 | LL16: 45929 | LM16: Veen, plantenresten, weinig, bruin, donker, Pulsinstallatie machinaal, Laag | LN16: weinig plantenresten | LO16: -4.16 | LP16: 13 | LQ16: 8.8959659 | LR16: 1.1127252 | LS16: 699.47552 | LT16: 717.68953 | LV16: 11.822271 | LW16: 10.291201 | LX16: 1454.4 | LY16: 20 | LZ16: 20 | MA16: 63 | MB16: 25 | MC16: 22 | MD16: Conform 1207808-007-GEO-0002-v3-r-Dijken op Veen II en 1230090-019-GEO-0002-v03-r-Protocol laboratoriumproeven voor grondonderzoek aan waterkeringen | ME16: Constante hoogte | MF16: 13 | MG16: 13 | MI16: 11.940136 | MJ16: 1 | MK16: 20.038752 | ML16: 5 | MM16: 1.1007412 | MN16: 11.518907 | MO16: 2.5756618 | MP16: 10.840877 | MQ16: 4.3218881 | MR16: 10.813499 | MS16: 5.7727629 | MT16: 10.604822 | MU16: 6.5232085 | MV16: 10.599748 | MW16: 6.995364 | MX16: 9.085012 | MY16: 7.6269284 | MZ16: 44.107813 | NA16: 9.3597299 | NB16: 7.4827825 | NC16: 40 | NG16: 99.603126 | QT16: DSS_voorbeeld | QV16: 13 | QX16: 13 | RB16: OC | RD16: OC | RE16: 25.5 | RF16: 12.5 | RG16: 9.75 | RJ16: 25.5 | RL16: 1.9615385
A17: =Table1[[#This Row],[ALG__REGEL]]&"_"&Table1[[#This Row],[BORING_NUMMER]]&"_"&Table1[[#This Row],[MONSTER_ID]] -> 10_B03-K01_5-1001 | B17: 10 | C17: FALSE | G17: FALSE | H17: FALSE | I17: TRUE | J17: FALSE | K17: Waterschap | L17: Voorbeeld | N17: Polderdijk | O17: B03-K | Q17: Regionaal | V17: 87513.65 | W17: 449526.42 | X17: -1.868 | Y17: B03-K01 | Z17: KR | AA17: 45754 | AB17: Voorbeeld.pdf | AD17: Voorbeeld | AF17: Pulsboor | AG17: -2.498 | AI17: 5-1001 | AK17: Koelruimte 10°C en 85% luchtvochtigheid | AL17: -4.268 | AM17: -4.668 | AN17: 2.4 | AO17: 2.8 | AT17: Voorbeeld | AW17: Veen, plantenresten, weinig, bruin, donker, Pulsinstallatie machinaal, Geen sterkte | AX17: weinig plantenresten | LG17: DSS18)GA250495_B03-K01_5-1001.pdf | LH17: DSS18)GA250495_B03-K01_5-1001_ASCII.txt | LI17: 5-1001 | LJ17: Voorbeeld | LK17: ASTM D6528 | LL17: 45929 | LM17: Veen, plantenresten, weinig, bruin, donker, Pulsinstallatie machinaal, Geen sterkte | LN17: weinig plantenresten | LO17: -4.56 | LP17: 13.5 | LQ17: 9.9445494 | LR17: 1.8155047 | LS17: 447.75673 | LT17: 461.29032 | LV17: 8.867251 | LW17: 7.623855 | LX17: 1826.1 | LY17: 20 | LZ17: 20 | MA17: 63 | MB17: 25 | MC17: 21.84 | MD17: Conform 1207808-007-GEO-0002-v3-r-Dijken op Veen II en 1230090-019-GEO-0002-v03-r-Protocol laboratoriumproeven voor grondonderzoek aan waterkeringen | ME17: Constante hoogte | MF17: 13.5 | MG17: 13.5 | MI17: 12.600215 | MJ17: 1 | MK17: 20.022036 | ML17: 5 | MM17: 1.0924845 | MN17: 11.477932 | MO17: 2.7976951 | MP17: 10.926156 | MQ17: 4.469961 | MR17: 10.705147 | MS17: 5.8516491 | MT17: 10.444194 | MU17: 6.65635 | MV17: 10.573136 | MW17: 7.1222891 | MX17: 11.349517 | MY17: 8.4258224 | MZ17: 44.970435 | NA17: 10.952088 | NB17: 8.2432131 | NC17: 40 | NG17: 97.024972 | QT17: DSS_voorbeeld | QV17: 13.5 | QX17: 13.5 | RB17: OC | RD17: OC | RG17: 9.75 | RH17: 23.25 | RJ17: 23.25 | RL17: 1.7222222
A18: =Table1[[#This Row],[ALG__REGEL]]&"_"&Table1[[#This Row],[BORING_NUMMER]]&"_"&Table1[[#This Row],[MONSTER_ID]] -> 11_B03-K02_1-E 201 | B18: 11 | C18: FALSE | G18: FALSE | H18: FALSE | I18: TRUE | J18: FALSE | K18: Waterschap | L18: Voorbeeld | N18: Polderdijk | O18: B03-K | Q18: Regionaal | V18: 87520.09 | W18: 449519.78 | X18: -1.904 | Y18: B03-K02 | Z18: KR | AA18: 45754 | AB18: Voorbeeld.pdf | AD18: Voorbeeld | AF18: Pulsboor | AG18: -2.504 | AI18: 1-E 201 | AK18: Koelruimte 10°C en 85% luchtvochtigheid | AL18: -2.704 | AM18: -3.104 | AN18: 0.8 | AO18: 1.2 | AT18: Voorbeeld | AW18: Veen, glas, weinig, bruin, donker, Pulsinstallatie machinaal, Geen sterkte | AX18: weinig glas | LG18: DSS20)GA250495_B03-K02_1-E 201.pdf | LH18: DSS20)GA250495_B03-K02_1-E 201_ASCII.txt | LI18: 1-E 201 | LJ18: Voorbeeld | LK18: ASTM D6528 | LL18: 45932 | LM18: Veen, glas, weinig, bruin, donker, Pulsinstallatie machinaal, Geen sterkte | LN18: weinig glas | LO18: -2.99 | LP18: 5.9 | LQ18: 10.273097 | LR18: 2.24724 | LS18: 357.14286 | LT18: 323.47526 | LV18: 6.5494446 | LW18: 6.0007634 | LX18: 1729.4 | LY18: 20 | LZ18: 20 | MA18: 63 | MB18: 25 | MC18: 23.18 | MD18: Conform 1207808-007-GEO-0002-v3-r-Dijken op Veen II en 1230090-019-GEO-0002-v03-r-Protocol laboratoriumproeven voor grondonderzoek aan waterkeringen | ME18: Constante hoogte | MF18: 5.9 | MG18: 5.9 | MI18: 7.2674344 | MJ18: 1 | MK18: 20.017657 | ML18: 5 | MM18: 1.1591521 | MN18: 4.7748506 | MO18: 2.5525164 | MP18: 4.7869673 | MQ18: 3.8360326 | MR18: 5.4027841 | MS18: 5.2085534 | MT18: 6.4156126 | MU18: 6.200133 | MV18: 7.3924466 | MW18: 6.9529697 | MX18: 11.481667 | MY18: 8.3141617 | MZ18: 44.086142 | NA18: 10.814179 | NB18: 8.2553174 | NC18: 40 | NG18: 71.263307 | QT18: DSS_voorbeeld | QV18: 5.9 | QX18: 5.9 | RB18: OC | RD18: OC | RG18: 12.2 | RH18: 18.1 | RI18: 30 | RJ18: 30 | RL18: 5.0847458
A19: =Table1[[#This Row],[ALG__REGEL]]&"_"&Table1[[#This Row],[BORING_NUMMER]]&"_"&Table1[[#This Row],[MONSTER_ID]] -> 12_B03-K02_2-507 | B19: 12 | C19: FALSE | G19: FALSE | H19: FALSE | I19: TRUE | J19: FALSE | K19: Waterschap | L19: Voorbeeld | N19: Polderdijk | O19: B03-K | Q19: Regionaal | V19: 87520.09 | W19: 449519.78 | X19: -1.904 | Y19: B03-K02 | Z19: KR | AA19: 45754 | AB19: Voorbeeld.pdf | AD19: Voorbeeld | AF19: Pulsboor | AG19: -2.504 | AI19: 2-507 | AK19: Koelruimte 10°C en 85% luchtvochtigheid | AL19: -3.104 | AM19: -3.504 | AN19: 1.2 | AO19: 1.6 | AT19: Voorbeeld | AW19: Veen, bruin, donker, Pulsinstallatie machinaal, Laag | LG19: DSS21)GA250495_B03-K02_2-507.pdf | LH19: DSS21)GA250495_B03-K02_2-507_ASCII.txt | LI19: 2-507 | LJ19: Voorbeeld | LK19: ASTM D6528 | LL19: 45938 | LM19: Veen, bruin, donker, Pulsinstallatie machinaal, Laag | LO19: -3.39 | LP19: 6.1 | LQ19: 9.1087037 | LR19: 1.2926999 | LS19: 604.62633 | LT19: 582.14616 | LV19: 9.955905 | LW19: 9.6488986 | LX19: 1443.7 | LY19: 20 | LZ19: 20 | MA19: 63 | MB19: 25 | MC19: 24.25 | MD19: Conform 1207808-007-GEO-0002-v3-r-Dijken op Veen II en 1230090-019-GEO-0002-v03-r-Protocol laboratoriumproeven voor grondonderzoek aan waterkeringen | ME19: Constante hoogte | MF19: 6.1 | MG19: 6.1 | MI19: 2.8019587 | MJ19: 1 | MK19: 20.021049 | ML19: 5 | MM19: 1.2149725 | MN19: 3.9085505 | MO19: 2.927288 | MP19: 3.3134602 | MQ19: 4.5465876 | MR19: 4.0216322 | MS19: 6.1071566 | MT19: 5.5988683 | MU19: 7.4836415 | MV19: 7.1670234 | MW19: 8.4557009 | MX19: 11.594995 | MY19: 9.9095029 | MZ19: 36.882392 | NA19: 12.219629 | NB19: 9.8626195 | NC19: 40 | NG19: 80.758755 | QT19: DSS_voorbeeld | QV19: 6.1 | QX19: 6.1 | RB19: OC | RD19: OC | RG19: 12.2 | RH19: 18.3 | RI19: 30 | RJ19: 30 | RL19: 4.9180328
A20: =Table1[[#This Row],[ALG__REGEL]]&"_"&Table1[[#This Row],[BORING_NUMMER]]&"_"&Table1[[#This Row],[MONSTER_ID]] -> 13_B03-K02_3-581 | B20: 13 | C20: FALSE | G20: FALSE | H20: FALSE | I20: TRUE | J20: FALSE | K20: Waterschap | L20: Voorbeeld | N20: Polderdijk | O20: B03-K | Q20: Regionaal | V20: 87520.09 | W20: 449519.78 | X20: -1.904 | Y20: B03-K02 | Z20: KR | AA20: 45754 | AB20: Voorbeeld.pdf | AD20: Voorbeeld | AF20: Pulsboor | AG20: -2.504 | AI20: 3-581 | AK20: Koelruimte 10°C en 85% luchtvochtigheid | AL20: -3.504 | AM20: -3.904 | AN20: 1.6 | AO20: 2 | AT20: Voorbeeld | AW20: Veen, bruin, donker, Pulsinstallatie machinaal, Laag | LG20: DSS22)GA250495_B03-K02_3-581.pdf | LH20: DSS22)GA250495_B03-K02_3-581_ASCII.txt | LI20: 3-581 | LJ20: Voorbeeld | LK20: ASTM D6528 | LL20: 45939 | LM20: Veen, bruin, donker, Pulsinstallatie machinaal, Laag | LO20: -3.79 | LP20: 6.4 | LQ20: 9.5392146 | LR20: 1.2424742 | LS20: 667.75956 | LT20: 652.62626 | LV20: 14.119952 | LW20: 13.238894 | LX20: 1915 | LY20: 20 | LZ20: 20 | MA20: 63 | MB20: 25 | MC20: 23.54 | MD20: Conform 1207808-007-GEO-0002-v3-r-Dijken op Veen II en 1230090-019-GEO-0002-v03-r-Protocol laboratoriumproeven voor grondonderzoek aan waterkeringen | ME20: Constante hoogte | MF20: 6.4 | MG20: 6.4 | MI20: 5.8266734 | MJ20: 1 | MK20: 20.01489 | ML20: 5 | MM20: 1.1771611 | MN20: 4.9228021 | MO20: 2.2358589 | MP20: 4.658286 | MQ20: 3.7189211 | MR20: 4.8883741 | MS20: 5.0952429 | MT20: 5.272744 | MU20: 5.8705856 | MV20: 5.8012182 | MW20: 6.4339105 | MX20: 8.0122474 | MY20: 7.1678116 | MZ20: 44.74236 | NA20: 7.7491099 | NB20: 7.0368875 | NC20: 40 | NG20: 77.275524 | QT20: DSS_voorbeeld | QV20: 6.4 | QX20: 6.4 | RB20: OC | RD20: OC | RG20: 12.2 | RH20: 18.6 | RI20: 30 | RJ20: 30 | RL20: 4.6875
